Workbook
Name \A: '[1]result-mi'!#REF!
Name \X: #REF!
Name \Y: #REF!
Name _1: #REF!
Name _2: '[1]result-mi'!#REF!
Name _3: #REF!
Name _4: '[1]result-mi'!#REF!
Name _5: '[1]result-mi'!#REF!
Name _DAT2: #REF!
Name aaaaaaaa: #N/A
Name asds: '[1]result-mi'!#REF!
Name Atualizacao_Variacao: #N/A
Name base: #REF!
Name Base_Precos: #REF!
Name Base_Rendimento: #REF!
Name Cad_Fam: #REF!
Name Carambei: [11]base!$CH$3:$CL$560
Name cbi: #REF!
Name cpz: #REF!
Name devers2: [12]MêsBase!$A$2:$Q$64
Name Divers: [13]MêsBase!$A$2:$Q$64
Name dsdsd: '[1]result-mi'!#REF!
Name dsfdsdsfg: '[1]result-mi'!#REF!
Name f: #N/A
Name frfsd: '[1]result-mi'!#REF!
Name Imprime_corrigido: #N/A
Name IMPRIME2: #N/A
Name Junho: '[1]result-mi'!#REF!
Name Local_Plan_ME: #N/A
Name MENU: '[1]result-mi'!#REF!
Name Módulo1.Local_Plan_ME: #N/A
Name Módulo1.Ocultar: #N/A
Name mrua: #REF!
Name mrus: #REF!
Name NvsASD: "V2001-12-31"
Name NvsAutoDrillOk: "VN"
Name NvsInstSpec: "%,FBU_FILIAL,TENTIDADES,NTMA"
Name NvsLayoutType: "M3"
Name NvsPanelEffdt: "V1990-01-01"
Name NvsPanelSetid: "VMODEL"
Name NvsReqBU: "VTEL"
Name NvsReqBUOnly: "VN"
Name NvsTransLed: "VN"
Name NvsTreeASD: "V2050-01-01"
Name NvsValTbl.BUSINESS_UNIT: "BUS_UNIT_TBL_GL"
Name Ocultar: #N/A
Name preço: [11]base!$A$3:$F$4003
Name RESACUM: #REF!
Name RESMES: #REF!
Name rre: '[1]result-mi'!#REF!
Name rveA: #REF!
Name rveS: #REF!
Name Sispec: [15]Sispec!$A$1:$M$65536
Name Sispec99: [16]Sispec99!$A$1:$M$65536
Name SispecPSAP: [17]SispecPSAP!$A$1:$M$65536
Name TabEmp: [16]Tabelas!$A$1:$C$74
Name TFRIG: '[1]result-mi'!#REF!
Name TNFRIG: '[1]result-mi'!#REF!
Name TNPIN: '[1]result-mi'!#REF!
Name TPIN: '[1]result-mi'!#REF!

Sheet COLAR PLANO
A1: CÓD. ITEM | C1: NOME DO ITEM | D1: Plano Mensal Alterado | E1: =SUBTOTAL(9,D2:D1204) -> 2160000 | F1: ='BD VOLUME'!F3 -> 2160000 | G1: =E1-F1 -> 0 | I1: =30/130 -> 0.23076923
A2: 985996 | C2: FRANGO CARC S/ MIUDOS CG | D2: =G2*1000 -> 0 | E2: =VLOOKUP(A2,'BD VOLUME'!A:F,6,0) -> 0 | G2: 0
A3: 797901 | C3: FRANGO INTEIRO CG PCT | D3: =G3*1000 -> 0 | E3: =VLOOKUP(A3,'BD VOLUME'!A:F,6,0) -> 0 | G3: 0
A4: 18244 | C4: COXINHA ASA CG ALM SE | D4: =G4*1000 -> 73324.8 | E4: =VLOOKUP(A4,'BD VOLUME'!A:F,6,0) -> 73324.8 | G4: 73.3248
A5: 990397 | C5: COXINHA DA ASA BDJ RF PRM | D5: =G5*1000 -> 1094.4 | E5: =VLOOKUP(A5,'BD VOLUME'!A:F,6,0) -> 1094.4 | G5: 1.0944
A6: 14290 | C6: MEIO ASA CG ALM | D6: =G6*1000 -> 56908.8 | E6: =VLOOKUP(A6,'BD VOLUME'!A:F,6,0) -> 56908.8 | G6: 56.9088
A7: 14133 | C7: ASA INT CG ITF SE | D7: =G7*1000 -> 87552 | E7: =VLOOKUP(A7,'BD VOLUME'!A:F,6,0) -> 87552 | G7: 87.552
A8: 997653 | C8: CARNE MS AVES CG CST MP ZG | D8: =G8*1000 -> 317088 | E8: =VLOOKUP(A8,'BD VOLUME'!A:F,6,0) -> 317088 | G8: 317.088
A9: 18163 | C9: CORACAO FGO CG ALM SE | D9: =G9*1000 -> 12096 | E9: =VLOOKUP(A9,'BD VOLUME'!A:F,6,0) -> 12096 | G9: 12.096
A10: 209669 | C10: FIGADO FG CG PCT | D10: =G10*1000 -> 42336 | E10: =VLOOKUP(A10,'BD VOLUME'!A:F,6,0) -> 42336 | G10: 42.336
A11: 14567 | C11: FILEZINHO PEITO CG BL SE | D11: =G11*1000 -> 120657.6 | E11: =VLOOKUP(A11,'BD VOLUME'!A:F,6,0) -> 120657.6 | G11: 120.6576
A12: 990389 | C12: FILEZINHO FG BDJ RF PRM 700G | D12: =G12*1000 -> 302.4 | E12: =VLOOKUP(A12,'BD VOLUME'!A:F,6,0) -> 302.4 | G12: 0.3024
A13: 18228 | C13: MOELA FRANGO CG ALM SE | D13: =G13*1000 -> 35712 | E13: =VLOOKUP(A13,'BD VOLUME'!A:F,6,0) -> 35712 | G13: 35.712
... A28: 55364 | C28: REC PEITO FGO CO MPL MP | D28: =G28*1000 -> 11232 | E28: =VLOOKUP(A28,'BD VOLUME'!A:F,6,0) -> 11232 | G28: 11.232
E29: =VLOOKUP(A29,'BD VOLUME'!A:F,6,0) -> #N/A
E30: =VLOOKUP(A30,'BD VOLUME'!A:F,6,0) -> #N/A
E31: =VLOOKUP(A31,'BD VOLUME'!A:F,6,0) -> #N/A
E32: =VLOOKUP(A32,'BD VOLUME'!A:F,6,0) -> #N/A
E33: =VLOOKUP(A33,'BD VOLUME'!A:F,6,0) -> #N/A
E34: =VLOOKUP(A34,'BD VOLUME'!A:F,6,0) -> #N/A
E35: =VLOOKUP(A35,'BD VOLUME'!A:F,6,0) -> #N/A
E36: =VLOOKUP(A36,'BD VOLUME'!A:F,6,0) -> #N/A
E37: =VLOOKUP(A37,'BD VOLUME'!A:F,6,0) -> #N/A
E38: =VLOOKUP(A38,'BD VOLUME'!A:F,6,0) -> #N/A
E39: =VLOOKUP(A39,'BD VOLUME'!A:F,6,0) -> #N/A
E40: =VLOOKUP(A40,'BD VOLUME'!A:F,6,0) -> #N/A
... E431: =VLOOKUP(A431,'BD VOLUME'!A:F,6,0) -> #N/A

Sheet BD VOLUME
B2: VELOCIDADE PADRÃO (FR/HORA) | C2: HORAS TRABALHADAS | D2: PESO MÉDIO FRANGO (KG) | E2: DIAS TRABALHADOS | F2: TOTAL PLANO DO SIMULADOR | G2: TOTAL PLANO DE PRODUÇÃO
A3: Grande | B3: =(SUM(Preencher!$I$13:$K$13)/(SUM(Preencher!$I$15:$K$16))) -> 4699.7389 | C3: =SUM(Preencher!$I$15:$K$16) -> 9.575 | D3: =Preencher!$I$23 -> 3 | E3: =Preencher!$I$11 -> 22 | F3: =SUBTOTAL(9,F8:F777) -> 2160000 | G3: ='COLAR PLANO'!E1 -> 2160000
A4: Pequeno | B4: =(SUM(Preencher!$I$14:$K$14)/(SUM(Preencher!$I$15:$K$16))) -> 0 | C4: =SUM(Preencher!$I$15:$K$16) -> 9.575 | D4: =Preencher!$I$24 -> 0 | E4: =Preencher!$I$11 -> 22
A6: Item | B6: Sigla | C6: Nm Item | D6: Família | E6: Sub Família | F6: Plano de Produção (kg/mês) | G6: Plano de produção (kg/hora) | H6: Rend. Prod. acabado | I6: Frangos/h | J6: % frangos desviados | K6: Peso pacote | L6: Nº pct/cx | M6: Peso Caxia | N6: pct/hr | O6: cx/hr Manual | P6: cx/hr Autom. | Q6: Bloc/hr CG | R6: Cx/hr RF | S6: Bloc/hr RF | T6: Lacr/hr | W6: MQ.TUNEL DE CG (CONTINUO) | X6: MQ.TUNEL DE CG (CONTINUO) (1) | Y6: MQ.TUNEL DE CG (CONTINUO) (2) | Z6: MQ.TUNEL DE CG (CONTINUO) (3) | AA6: MQ.TUNEL DE CG (ESTATICO) | AB6: MQ.TUNEL DE CG (ESTATICO) (1) | AC6: MQ.TUNEL DE CG (ESTATICO) (2) | AD6: Capacidade Tunel | AE6: Horas de tunel | AF6: MQ.GIROFREEZER | AG6: MQ.GIROFREEZER (1) | AH6: MQ.GIROFREEZER (2) | AI6: MQ.GIROFREEZER REV04 | AJ6: MQ.GIROFREEZER (3) | AK6: Capacidade Giro | AL6: Horas de giro
A7: MIUDOS | B7: =B3+B4 -> 4699.7389 | D7: =((B3*D3)+(B4*D4))/(B3+B4) -> 3 | AD7: =LARGE(AD8:AD1203,1) -> 0 | AE7: =SUBTOTAL(9,AE8:AE1203) -> 0 | AK7: =LARGE(AK8:AK1203,1) -> 0 | AL7: =SUBTOTAL(9,AL8:AL1203) -> 0
A8: 964310 | B8: 964310 | C8: MOELA FG CG PCT | D8: MIUDOS | E8: MOELA PACOTE 1 KG | F8: =SUMIF('COLAR PLANO'!$A:$A,A8,'COLAR PLANO'!$D:$D) -> 0 | G8: =IFERROR(F8/($E$3*$C$3),0) -> 0 | H8: 0.0106 | I8: =IFERROR(G8/$D$7/H8,0) -> 0 | J8: =IFERROR(I8/$B$7,0) -> 0 | K8: 1 | L8: 12 | M8: 12 | N8: =IFERROR(G8/K8,"-") -> 0 | P8: =IFERROR(G8/M8,"-") -> 0 | U8: - | V8: FRG | W8: =Preencher!$B$3&U8&V8&A8&$W$6 -> JARINU-FRG964310MQ.TUNEL DE CG (CONTINUO) | X8: =Preencher!$B$3&U8&V8&A8&$X$6 -> JARINU-FRG964310MQ.TUNEL DE CG (CONTINUO) (1) | Y8: =Preencher!$B$3&U8&V8&A8&$Y$6 -> JARINU-FRG964310MQ.TUNEL DE CG (CONTINUO) (2) | Z8: =Preencher!$B$3&U8&V8&A8&$Z$6 -> JARINU-FRG964310MQ.TUNEL DE CG (CONTINUO) (3) | AA8: =Preencher!$B$3&U8&V8&A8&$AA$6 -> JARINU-FRG964310MQ.TUNEL DE CG (ESTATICO) | AB8: =Preencher!$B$3&U8&V8&A8&$AB$6 -> JARINU-FRG964310MQ.TUNEL DE CG (ESTATICO) (1) | AC8: =Preencher!$B$3&U8&V8&A8&$AC$6 -> JARINU-FRG964310MQ.TUNEL DE CG (ESTATICO) (2) | AD8: =IFERROR(SUMIF('BD Otimix'!A:A,'BD VOLUME'!X8,'BD Otimix'!O:O)+SUMIF('BD Otimix'!A:A,'BD VOLUME'!Y8,'BD Otimix'!O:O)+SUMIF('BD Otimix'!A:A,'BD VOLUME'!Z8,'BD Otimix'!O:O)+SUMIF('BD Otimix'!A:A,'BD VOLUME'!AA8,'BD Otimix'!O:O)+SUMIF('BD Otimix'!A:A,'BD VOLUME'!AB8,'BD Otimix'!O:O)+SUMIF('BD Otimix'!A:A,'BD VOLUME'!AC8,'BD Otimix'!O:O)+SUMIF('BD Otimix'!A:A,'BD VOLUME'!W8,'BD Otimix'!O:O),0) -> 0 | AE8: =IFERROR(F8/$E$3/1000/AD8,0) -> 0 | AF8: =Preencher!$B$3&$U$8&$V$8&A8&$AF$6 -> JARINU-FRG964310MQ.GIROFREEZER | AG8: =Preencher!$B$3&$U$8&$V$8&A8&$AG$6 -> JARINU-FRG964310MQ.GIROFREEZER (1) | AH8: =Preencher!$B$3&$U$8&$V$8&A8&$AH$6 -> JARINU-FRG964310MQ.GIROFREEZER (2) | AI8: =Preencher!$B$3&$U$8&$V$8&A8&$AI$6 -> JARINU-FRG964310MQ.GIROFREEZER REV04 | AJ8: =Preencher!$B$3&$U$8&$V$8&A8&$AJ$6 -> JARINU-FRG964310MQ.GIROFREEZER (3) | AK8: =IFERROR(SUMIF('BD Otimix'!A:A,'BD VOLUME'!AG8,'BD Otimix'!O:O)+SUMIF('BD Otimix'!A:A,'BD VOLUME'!AH8,'BD Otimix'!O:O)+SUMIF('BD Otimix'!A:A,'BD VOLUME'!AI8,'BD Otimix'!O:O)+SUMIF('BD Otimix'!A:A,'BD VOLUME'!AJ8,'BD Otimix'!O:O)+SUMIF('BD Otimix'!A:A,'BD VOLUME'!AF8,'BD Otimix'!O:O),0) -> 0 | AL8: =IFERROR(F8/$E$3/1000/AK8,0) -> 0
A9: 40843 | B9: GI-32 | C9: MOELA FG PB | D9: MIUDOS | E9: MOELA PACOTE 1 KG | F9: =SUMIF('COLAR PLANO'!$A:$A,A9,'COLAR PLANO'!$D:$D) -> 0 | G9: =IFERROR(F9/($E$3*$C$3),0) -> 0 | H9: 0.0106 | I9: =IFERROR(G9/$D$7/H9,0) -> 0 | J9: =IFERROR(I9/$B$7,0) -> 0 | K9: 1 | L9: 12 | M9: 12 | N9: =IFERROR(G9/K9,"-") -> 0 | P9: =IFERROR(G9/M9,"-") -> 0 | U9: - | V9: FRG | W9: =Preencher!$B$3&U9&V9&A9&$W$6 -> JARINU-FRG40843MQ.TUNEL DE CG (CONTINUO) | X9: =Preencher!$B$3&U9&V9&A9&$X$6 -> JARINU-FRG40843MQ.TUNEL DE CG (CONTINUO) (1) | Y9: =Preencher!$B$3&U9&V9&A9&$Y$6 -> JARINU-FRG40843MQ.TUNEL DE CG (CONTINUO) (2) | Z9: =Preencher!$B$3&U9&V9&A9&$Z$6 -> JARINU-FRG40843MQ.TUNEL DE CG (CONTINUO) (3) | AA9: =Preencher!$B$3&U9&V9&A9&$AA$6 -> JARINU-FRG40843MQ.TUNEL DE CG (ESTATICO) | AB9: =Preencher!$B$3&U9&V9&A9&$AB$6 -> JARINU-FRG40843MQ.TUNEL DE CG (ESTATICO) (1) | AC9: =Preencher!$B$3&U9&V9&A9&$AC$6 -> JARINU-FRG40843MQ.TUNEL DE CG (ESTATICO) (2) | AD9: =IFERROR(SUMIF('BD Otimix'!A:A,'BD VOLUME'!X9,'BD Otimix'!O:O)+SUMIF('BD Otimix'!A:A,'BD VOLUME'!Y9,'BD Otimix'!O:O)+SUMIF('BD Otimix'!A:A,'BD VOLUME'!Z9,'BD Otimix'!O:O)+SUMIF('BD Otimix'!A:A,'BD VOLUME'!AA9,'BD Otimix'!O:O)+SUMIF('BD Otimix'!A:A,'BD VOLUME'!AB9,'BD Otimix'!O:O)+SUMIF('BD Otimix'!A:A,'BD VOLUME'!AC9,'BD Otimix'!O:O)+SUMIF('BD Otimix'!A:A,'BD VOLUME'!W9,'BD Otimix'!O:O),0) -> 0 | AE9: =IFERROR(F9/$E$3/1000/AD9,0) -> 0 | AF9: =Preencher!$B$3&$U$8&$V$8&A9&$AF$6 -> JARINU-FRG40843MQ.GIROFREEZER | AG9: =Preencher!$B$3&$U$8&$V$8&A9&$AG$6 -> JARINU-FRG40843MQ.GIROFREEZER (1) | AH9: =Preencher!$B$3&$U$8&$V$8&A9&$AH$6 -> JARINU-FRG40843MQ.GIROFREEZER (2) | AI9: =Preencher!$B$3&$U$8&$V$8&A9&$AI$6 -> JARINU-FRG40843MQ.GIROFREEZER REV04 | AJ9: =Preencher!$B$3&$U$8&$V$8&A9&$AJ$6 -> JARINU-FRG40843MQ.GIROFREEZER (3) | AK9: =IFERROR(SUMIF('BD Otimix'!A:A,'BD VOLUME'!AG9,'BD Otimix'!O:O)+SUMIF('BD Otimix'!A:A,'BD VOLUME'!AH9,'BD Otimix'!O:O)+SUMIF('BD Otimix'!A:A,'BD VOLUME'!AI9,'BD Otimix'!O:O)+SUMIF('BD Otimix'!A:A,'BD VOLUME'!AJ9,'BD Otimix'!O:O)+SUMIF('BD Otimix'!A:A,'BD VOLUME'!AF9,'BD Otimix'!O:O),0) -> 0 | AL9: =IFERROR(F9/$E$3/1000/AK9,0) -> 0
A10: 1039 | B10: GI-105 | C10: MOELA FG PB | D10: MIUDOS | E10: MOELA PACOTE 1 KG | F10: =SUMIF('COLAR PLANO'!$A:$A,A10,'COLAR PLANO'!$D:$D) -> 0 | G10: =IFERROR(F10/($E$3*$C$3),0) -> 0 | H10: 0.0106 | I10: =IFERROR(G10/$D$7/H10,0) -> 0 | J10: =IFERROR(I10/$B$7,0) -> 0 | K10: 1 | L10: 12 | M10: 12 | N10: =IFERROR(G10/K10,"-") -> 0 | P10: =IFERROR(G10/M10,"-") -> 0 | U10: - | V10: FRG | W10: =Preencher!$B$3&U10&V10&A10&$W$6 -> JARINU-FRG1039MQ.TUNEL DE CG (CONTINUO) | X10: =Preencher!$B$3&U10&V10&A10&$X$6 -> JARINU-FRG1039MQ.TUNEL DE CG (CONTINUO) (1) | Y10: =Preencher!$B$3&U10&V10&A10&$Y$6 -> JARINU-FRG1039MQ.TUNEL DE CG (CONTINUO) (2) | Z10: =Preencher!$B$3&U10&V10&A10&$Z$6 -> JARINU-FRG1039MQ.TUNEL DE CG (CONTINUO) (3) | AA10: =Preencher!$B$3&U10&V10&A10&$AA$6 -> JARINU-FRG1039MQ.TUNEL DE CG (ESTATICO) | AB10: =Preencher!$B$3&U10&V10&A10&$AB$6 -> JARINU-FRG1039MQ.TUNEL DE CG (ESTATICO) (1) | AC10: =Preencher!$B$3&U10&V10&A10&$AC$6 -> JARINU-FRG1039MQ.TUNEL DE CG (ESTATICO) (2) | AD10: =IFERROR(SUMIF('BD Otimix'!A:A,'BD VOLUME'!X10,'BD Otimix'!O:O)+SUMIF('BD Otimix'!A:A,'BD VOLUME'!Y10,'BD Otimix'!O:O)+SUMIF('BD Otimix'!A:A,'BD VOLUME'!Z10,'BD Otimix'!O:O)+SUMIF('BD Otimix'!A:A,'BD VOLUME'!AA10,'BD Otimix'!O:O)+SUMIF('BD Otimix'!A:A,'BD VOLUME'!AB10,'BD Otimix'!O:O)+SUMIF('BD Otimix'!A:A,'BD VOLUME'!AC10,'BD Otimix'!O:O)+SUMIF('BD Otimix'!A:A,'BD VOLUME'!W10,'BD Otimix'!O:O),0) -> 0 | AE10: =IFERROR(F10/$E$3/1000/AD10,0) -> 0 | AF10: =Preencher!$B$3&$U$8&$V$8&A10&$AF$6 -> JARINU-FRG1039MQ.GIROFREEZER | AG10: =Preencher!$B$3&$U$8&$V$8&A10&$AG$6 -> JARINU-FRG1039MQ.GIROFREEZER (1) | AH10: =Preencher!$B$3&$U$8&$V$8&A10&$AH$6 -> JARINU-FRG1039MQ.GIROFREEZER (2) | AI10: =Preencher!$B$3&$U$8&$V$8&A10&$AI$6 -> JARINU-FRG1039MQ.GIROFREEZER REV04 | AJ10: =Preencher!$B$3&$U$8&$V$8&A10&$AJ$6 -> JARINU-FRG1039MQ.GIROFREEZER (3) | AK10: =IFERROR(SUMIF('BD Otimix'!A:A,'BD VOLUME'!AG10,'BD Otimix'!O:O)+SUMIF('BD Otimix'!A:A,'BD VOLUME'!AH10,'BD Otimix'!O:O)+SUMIF('BD Otimix'!A:A,'BD VOLUME'!AI10,'BD Otimix'!O:O)+SUMIF('BD Otimix'!A:A,'BD VOLUME'!AJ10,'BD Otimix'!O:O)+SUMIF('BD Otimix'!A:A,'BD VOLUME'!AF10,'BD Otimix'!O:O),0) -> 0 | AL10: =IFERROR(F10/$E$3/1000/AK10,0) -> 0
A11: 44903 | B11: GI-13 | C11: MOELA FG PB | D11: MIUDOS | E11: MOELA PACOTE 1 KG | F11: =SUMIF('COLAR PLANO'!$A:$A,A11,'COLAR PLANO'!$D:$D) -> 0 | G11: =IFERROR(F11/($E$3*$C$3),0) -> 0 | H11: 0.0106 | I11: =IFERROR(G11/$D$7/H11,0) -> 0 | J11: =IFERROR(I11/$B$7,0) -> 0 | K11: 1 | L11: 16 | M11: 16 | N11: =IFERROR(G11/K11,"-") -> 0 | P11: =IFERROR(G11/M11,"-") -> 0 | U11: - | V11: FRG | W11: =Preencher!$B$3&U11&V11&A11&$W$6 -> JARINU-FRG44903MQ.TUNEL DE CG (CONTINUO) | X11: =Preencher!$B$3&U11&V11&A11&$X$6 -> JARINU-FRG44903MQ.TUNEL DE CG (CONTINUO) (1) | Y11: =Preencher!$B$3&U11&V11&A11&$Y$6 -> JARINU-FRG44903MQ.TUNEL DE CG (CONTINUO) (2) | Z11: =Preencher!$B$3&U11&V11&A11&$Z$6 -> JARINU-FRG44903MQ.TUNEL DE CG (CONTINUO) (3) | AA11: =Preencher!$B$3&U11&V11&A11&$AA$6 -> JARINU-FRG44903MQ.TUNEL DE CG (ESTATICO) | AB11: =Preencher!$B$3&U11&V11&A11&$AB$6 -> JARINU-FRG44903MQ.TUNEL DE CG (ESTATICO) (1) | AC11: =Preencher!$B$3&U11&V11&A11&$AC$6 -> JARINU-FRG44903MQ.TUNEL DE CG (ESTATICO) (2) | AD11: =IFERROR(SUMIF('BD Otimix'!A:A,'BD VOLUME'!X11,'BD Otimix'!O:O)+SUMIF('BD Otimix'!A:A,'BD VOLUME'!Y11,'BD Otimix'!O:O)+SUMIF('BD Otimix'!A:A,'BD VOLUME'!Z11,'BD Otimix'!O:O)+SUMIF('BD Otimix'!A:A,'BD VOLUME'!AA11,'BD Otimix'!O:O)+SUMIF('BD Otimix'!A:A,'BD VOLUME'!AB11,'BD Otimix'!O:O)+SUMIF('BD Otimix'!A:A,'BD VOLUME'!AC11,'BD Otimix'!O:O)+SUMIF('BD Otimix'!A:A,'BD VOLUME'!W11,'BD Otimix'!O:O),0) -> 0 | AE11: =IFERROR(F11/$E$3/1000/AD11,0) -> 0 | AF11: =Preencher!$B$3&$U$8&$V$8&A11&$AF$6 -> JARINU-FRG44903MQ.GIROFREEZER | AG11: =Preencher!$B$3&$U$8&$V$8&A11&$AG$6 -> JARINU-FRG44903MQ.GIROFREEZER (1) | AH11: =Preencher!$B$3&$U$8&$V$8&A11&$AH$6 -> JARINU-FRG44903MQ.GIROFREEZER (2) | AI11: =Preencher!$B$3&$U$8&$V$8&A11&$AI$6 -> JARINU-FRG44903MQ.GIROFREEZER REV04 | AJ11: =Preencher!$B$3&$U$8&$V$8&A11&$AJ$6 -> JARINU-FRG44903MQ.GIROFREEZER (3) | AK11: =IFERROR(SUMIF('BD Otimix'!A:A,'BD VOLUME'!AG11,'BD Otimix'!O:O)+SUMIF('BD Otimix'!A:A,'BD VOLUME'!AH11,'BD Otimix'!O:O)+SUMIF('BD Otimix'!A:A,'BD VOLUME'!AI11,'BD Otimix'!O:O)+SUMIF('BD Otimix'!A:A,'BD VOLUME'!AJ11,'BD Otimix'!O:O)+SUMIF('BD Otimix'!A:A,'BD VOLUME'!AF11,'BD Otimix'!O:O),0) -> 0 | AL11: =IFERROR(F11/$E$3/1000/AK11,0) -> 0
A12: 18228 | B12: MOE PC | C12: MOELA FRANGO CG ALM SE | D12: MIUDOS | E12: MOELA PACOTE 1 KG | F12: =SUMIF('COLAR PLANO'!$A:$A,A12,'COLAR PLANO'!$D:$D) -> 35712 | G12: =IFERROR(F12/($E$3*$C$3),0) -> 169.5324 | H12: 0.0106 | I12: =IFERROR(G12/$D$7/H12,0) -> 5331.2075 | J12: =IFERROR(I12/$B$7,0) -> 1.1343625 | K12: 1 | L12: 18 | M12: 18 | N12: =IFERROR(G12/K12,"-") -> 169.5324 | P12: =IFERROR(G12/M12,"-") -> 9.4184667 | U12: - | V12: FRG | W12: =Preencher!$B$3&U12&V12&A12&$W$6 -> JARINU-FRG18228MQ.TUNEL DE CG (CONTINUO) | X12: =Preencher!$B$3&U12&V12&A12&$X$6 -> JARINU-FRG18228MQ.TUNEL DE CG (CONTINUO) (1) | Y12: =Preencher!$B$3&U12&V12&A12&$Y$6 -> JARINU-FRG18228MQ.TUNEL DE CG (CONTINUO) (2) | Z12: =Preencher!$B$3&U12&V12&A12&$Z$6 -> JARINU-FRG18228MQ.TUNEL DE CG (CONTINUO) (3) | AA12: =Preencher!$B$3&U12&V12&A12&$AA$6 -> JARINU-FRG18228MQ.TUNEL DE CG (ESTATICO) | AB12: =Preencher!$B$3&U12&V12&A12&$AB$6 -> JARINU-FRG18228MQ.TUNEL DE CG (ESTATICO) (1) | AC12: =Preencher!$B$3&U12&V12&A12&$AC$6 -> JARINU-FRG18228MQ.TUNEL DE CG (ESTATICO) (2) | AD12: =IFERROR(SUMIF('BD Otimix'!A:A,'BD VOLUME'!X12,'BD Otimix'!O:O)+SUMIF('BD Otimix'!A:A,'BD VOLUME'!Y12,'BD Otimix'!O:O)+SUMIF('BD Otimix'!A:A,'BD VOLUME'!Z12,'BD Otimix'!O:O)+SUMIF('BD Otimix'!A:A,'BD VOLUME'!AA12,'BD Otimix'!O:O)+SUMIF('BD Otimix'!A:A,'BD VOLUME'!AB12,'BD Otimix'!O:O)+SUMIF('BD Otimix'!A:A,'BD VOLUME'!AC12,'BD Otimix'!O:O)+SUMIF('BD Otimix'!A:A,'BD VOLUME'!W12,'BD Otimix'!O:O),0) -> 0 | AE12: =IFERROR(F12/$E$3/1000/AD12,0) -> 0 | AF12: =Preencher!$B$3&$U$8&$V$8&A12&$AF$6 -> JARINU-FRG18228MQ.GIROFREEZER | AG12: =Preencher!$B$3&$U$8&$V$8&A12&$AG$6 -> JARINU-FRG18228MQ.GIROFREEZER (1) | AH12: =Preencher!$B$3&$U$8&$V$8&A12&$AH$6 -> JARINU-FRG18228MQ.GIROFREEZER (2) | AI12: =Preencher!$B$3&$U$8&$V$8&A12&$AI$6 -> JARINU-FRG18228MQ.GIROFREEZER REV04 | AJ12: =Preencher!$B$3&$U$8&$V$8&A12&$AJ$6 -> JARINU-FRG18228MQ.GIROFREEZER (3) | AK12: =IFERROR(SUMIF('BD Otimix'!A:A,'BD VOLUME'!AG12,'BD Otimix'!O:O)+SUMIF('BD Otimix'!A:A,'BD VOLUME'!AH12,'BD Otimix'!O:O)+SUMIF('BD Otimix'!A:A,'BD VOLUME'!AI12,'BD Otimix'!O:O)+SUMIF('BD Otimix'!A:A,'BD VOLUME'!AJ12,'BD Otimix'!O:O)+SUMIF('BD Otimix'!A:A,'BD VOLUME'!AF12,'BD Otimix'!O:O),0) -> 0 | AL12: =IFERROR(F12/$E$3/1000/AK12,0) -> 0
A13: 236769 | C13: MOELA FG BDJ GF | D13: MIUDOS | E13: MOELA BDJ CG | F13: =SUMIF('COLAR PLANO'!$A:$A,A13,'COLAR PLANO'!$D:$D) -> 0 | G13: =IFERROR(F13/($E$3*$C$3),0) -> 0 | H13: 0.0106 | I13: =IFERROR(G13/$D$7/H13,0) -> 0 | J13: =IFERROR(I13/$B$7,0) -> 0 | K13: 0.45 | L13: 16 | M13: 9 | N13: =IFERROR(G13/K13,"-") -> 0 | P13: =IFERROR(G13/M13,"-") -> 0 | U13: - | V13: FRG | W13: =Preencher!$B$3&U13&V13&A13&$W$6 -> JARINU-FRG236769MQ.TUNEL DE CG (CONTINUO) | X13: =Preencher!$B$3&U13&V13&A13&$X$6 -> JARINU-FRG236769MQ.TUNEL DE CG (CONTINUO) (1) | Y13: =Preencher!$B$3&U13&V13&A13&$Y$6 -> JARINU-FRG236769MQ.TUNEL DE CG (CONTINUO) (2) | Z13: =Preencher!$B$3&U13&V13&A13&$Z$6 -> JARINU-FRG236769MQ.TUNEL DE CG (CONTINUO) (3) | AA13: =Preencher!$B$3&U13&V13&A13&$AA$6 -> JARINU-FRG236769MQ.TUNEL DE CG (ESTATICO) | AB13: =Preencher!$B$3&U13&V13&A13&$AB$6 -> JARINU-FRG236769MQ.TUNEL DE CG (ESTATICO) (1) | AC13: =Preencher!$B$3&U13&V13&A13&$AC$6 -> JARINU-FRG236769MQ.TUNEL DE CG (ESTATICO) (2) | AD13: =IFERROR(SUMIF('BD Otimix'!A:A,'BD VOLUME'!X13,'BD Otimix'!O:O)+SUMIF('BD Otimix'!A:A,'BD VOLUME'!Y13,'BD Otimix'!O:O)+SUMIF('BD Otimix'!A:A,'BD VOLUME'!Z13,'BD Otimix'!O:O)+SUMIF('BD Otimix'!A:A,'BD VOLUME'!AA13,'BD Otimix'!O:O)+SUMIF('BD Otimix'!A:A,'BD VOLUME'!AB13,'BD Otimix'!O:O)+SUMIF('BD Otimix'!A:A,'BD VOLUME'!AC13,'BD Otimix'!O:O)+SUMIF('BD Otimix'!A:A,'BD VOLUME'!W13,'BD Otimix'!O:O),0) -> 0 | AE13: =IFERROR(F13/$E$3/1000/AD13,0) -> 0 | AF13: =Preencher!$B$3&$U$8&$V$8&A13&$AF$6 -> JARINU-FRG236769MQ.GIROFREEZER | AG13: =Preencher!$B$3&$U$8&$V$8&A13&$AG$6 -> JARINU-FRG236769MQ.GIROFREEZER (1) | AH13: =Preencher!$B$3&$U$8&$V$8&A13&$AH$6 -> JARINU-FRG236769MQ.GIROFREEZER (2) | AI13: =Preencher!$B$3&$U$8&$V$8&A13&$AI$6 -> JARINU-FRG236769MQ.GIROFREEZER REV04 | AJ13: =Preencher!$B$3&$U$8&$V$8&A13&$AJ$6 -> JARINU-FRG236769MQ.GIROFREEZER (3) | AK13: =IFERROR(SUMIF('BD Otimix'!A:A,'BD VOLUME'!AG13,'BD Otimix'!O:O)+SUMIF('BD Otimix'!A:A,'BD VOLUME'!AH13,'BD Otimix'!O:O)+SUMIF('BD Otimix'!A:A,'BD VOLUME'!AI13,'BD Otimix'!O:O)+SUMIF('BD Otimix'!A:A,'BD VOLUME'!AJ13,'BD Otimix'!O:O)+SUMIF('BD Otimix'!A:A,'BD VOLUME'!AF13,'BD Otimix'!O:O),0) -> 0 | AL13: =IFERROR(F13/$E$3/1000/AK13,0) -> 0
A14: 227909 | C14: MOELA FG BDJ NGF | D14: MIUDOS | E14: MOELA BDJ CG | F14: =SUMIF('COLAR PLANO'!$A:$A,A14,'COLAR PLANO'!$D:$D) -> 0 | G14: =IFERROR(F14/($E$3*$C$3),0) -> 0 | H14: 0.0106 | I14: =IFERROR(G14/$D$7/H14,0) -> 0 | J14: =IFERROR(I14/$B$7,0) -> 0 | K14: 1 | L14: 12 | M14: 12 | N14: =IFERROR(G14/K14,"-") -> 0 | P14: =IFERROR(G14/M14,"-") -> 0 | U14: - | V14: FRG | W14: =Preencher!$B$3&U14&V14&A14&$W$6 -> JARINU-FRG227909MQ.TUNEL DE CG (CONTINUO) | X14: =Preencher!$B$3&U14&V14&A14&$X$6 -> JARINU-FRG227909MQ.TUNEL DE CG (CONTINUO) (1) | Y14: =Preencher!$B$3&U14&V14&A14&$Y$6 -> JARINU-FRG227909MQ.TUNEL DE CG (CONTINUO) (2) | Z14: =Preencher!$B$3&U14&V14&A14&$Z$6 -> JARINU-FRG227909MQ.TUNEL DE CG (CONTINUO) (3) | AA14: =Preencher!$B$3&U14&V14&A14&$AA$6 -> JARINU-FRG227909MQ.TUNEL DE CG (ESTATICO) | AB14: =Preencher!$B$3&U14&V14&A14&$AB$6 -> JARINU-FRG227909MQ.TUNEL DE CG (ESTATICO) (1) | AC14: =Preencher!$B$3&U14&V14&A14&$AC$6 -> JARINU-FRG227909MQ.TUNEL DE CG (ESTATICO) (2) | AD14: =IFERROR(SUMIF('BD Otimix'!A:A,'BD VOLUME'!X14,'BD Otimix'!O:O)+SUMIF('BD Otimix'!A:A,'BD VOLUME'!Y14,'BD Otimix'!O:O)+SUMIF('BD Otimix'!A:A,'BD VOLUME'!Z14,'BD Otimix'!O:O)+SUMIF('BD Otimix'!A:A,'BD VOLUME'!AA14,'BD Otimix'!O:O)+SUMIF('BD Otimix'!A:A,'BD VOLUME'!AB14,'BD Otimix'!O:O)+SUMIF('BD Otimix'!A:A,'BD VOLUME'!AC14,'BD Otimix'!O:O)+SUMIF('BD Otimix'!A:A,'BD VOLUME'!W14,'BD Otimix'!O:O),0) -> 0 | AE14: =IFERROR(F14/$E$3/1000/AD14,0) -> 0 | AF14: =Preencher!$B$3&$U$8&$V$8&A14&$AF$6 -> JARINU-FRG227909MQ.GIROFREEZER | AG14: =Preencher!$B$3&$U$8&$V$8&A14&$AG$6 -> JARINU-FRG227909MQ.GIROFREEZER (1) | AH14: =Preencher!$B$3&$U$8&$V$8&A14&$AH$6 -> JARINU-FRG227909MQ.GIROFREEZER (2) | AI14: =Preencher!$B$3&$U$8&$V$8&A14&$AI$6 -> JARINU-FRG227909MQ.GIROFREEZER REV04 | AJ14: =Preencher!$B$3&$U$8&$V$8&A14&$AJ$6 -> JARINU-FRG227909MQ.GIROFREEZER (3) | AK14: =IFERROR(SUMIF('BD Otimix'!A:A,'BD VOLUME'!AG14,'BD Otimix'!O:O)+SUMIF('BD Otimix'!A:A,'BD VOLUME'!AH14,'BD Otimix'!O:O)+SUMIF('BD Otimix'!A:A,'BD VOLUME'!AI14,'BD Otimix'!O:O)+SUMIF('BD Otimix'!A:A,'BD VOLUME'!AJ14,'BD Otimix'!O:O)+SUMIF('BD Otimix'!A:A,'BD VOLUME'!AF14,'BD Otimix'!O:O),0) -> 0 | AL14: =IFERROR(F14/$E$3/1000/AK14,0) -> 0
A15: 999541 | C15: MIUDOS CONGELADOS DE FRANGO | D15: MIUDOS | E15: MOELA BDJ CG | F15: =SUMIF('COLAR PLANO'!$A:$A,A15,'COLAR PLANO'!$D:$D) -> 0 | G15: =IFERROR(F15/($E$3*$C$3),0) -> 0 | H15: 0.0106 | I15: =IFERROR(G15/$D$7/H15,0) -> 0 | J15: =IFERROR(I15/$B$7,0) -> 0 | K15: 0.45 | L15: 20 | M15: 9 | N15: =IFERROR(G15/K15,"-") -> 0 | P15: =IFERROR(G15/M15,"-") -> 0 | U15: - | V15: FRG | W15: =Preencher!$B$3&U15&V15&A15&$W$6 -> JARINU-FRG999541MQ.TUNEL DE CG (CONTINUO) | X15: =Preencher!$B$3&U15&V15&A15&$X$6 -> JARINU-FRG999541MQ.TUNEL DE CG (CONTINUO) (1) | Y15: =Preencher!$B$3&U15&V15&A15&$Y$6 -> JARINU-FRG999541MQ.TUNEL DE CG (CONTINUO) (2) | Z15: =Preencher!$B$3&U15&V15&A15&$Z$6 -> JARINU-FRG999541MQ.TUNEL DE CG (CONTINUO) (3) | AA15: =Preencher!$B$3&U15&V15&A15&$AA$6 -> JARINU-FRG999541MQ.TUNEL DE CG (ESTATICO) | AB15: =Preencher!$B$3&U15&V15&A15&$AB$6 -> JARINU-FRG999541MQ.TUNEL DE CG (ESTATICO) (1) | AC15: =Preencher!$B$3&U15&V15&A15&$AC$6 -> JARINU-FRG999541MQ.TUNEL DE CG (ESTATICO) (2) | AD15: =IFERROR(SUMIF('BD Otimix'!A:A,'BD VOLUME'!X15,'BD Otimix'!O:O)+SUMIF('BD Otimix'!A:A,'BD VOLUME'!Y15,'BD Otimix'!O:O)+SUMIF('BD Otimix'!A:A,'BD VOLUME'!Z15,'BD Otimix'!O:O)+SUMIF('BD Otimix'!A:A,'BD VOLUME'!AA15,'BD Otimix'!O:O)+SUMIF('BD Otimix'!A:A,'BD VOLUME'!AB15,'BD Otimix'!O:O)+SUMIF('BD Otimix'!A:A,'BD VOLUME'!AC15,'BD Otimix'!O:O)+SUMIF('BD Otimix'!A:A,'BD VOLUME'!W15,'BD Otimix'!O:O),0) -> 0 | AE15: =IFERROR(F15/$E$3/1000/AD15,0) -> 0 | AF15: =Preencher!$B$3&$U$8&$V$8&A15&$AF$6 -> JARINU-FRG999541MQ.GIROFREEZER | AG15: =Preencher!$B$3&$U$8&$V$8&A15&$AG$6 -> JARINU-FRG999541MQ.GIROFREEZER (1) | AH15: =Preencher!$B$3&$U$8&$V$8&A15&$AH$6 -> JARINU-FRG999541MQ.GIROFREEZER (2) | AI15: =Preencher!$B$3&$U$8&$V$8&A15&$AI$6 -> JARINU-FRG999541MQ.GIROFREEZER REV04 | AJ15: =Preencher!$B$3&$U$8&$V$8&A15&$AJ$6 -> JARINU-FRG999541MQ.GIROFREEZER (3) | AK15: =IFERROR(SUMIF('BD Otimix'!A:A,'BD VOLUME'!AG15,'BD Otimix'!O:O)+SUMIF('BD Otimix'!A:A,'BD VOLUME'!AH15,'BD Otimix'!O:O)+SUMIF('BD Otimix'!A:A,'BD VOLUME'!AI15,'BD Otimix'!O:O)+SUMIF('BD Otimix'!A:A,'BD VOLUME'!AJ15,'BD Otimix'!O:O)+SUMIF('BD Otimix'!A:A,'BD VOLUME'!AF15,'BD Otimix'!O:O),0) -> 0 | AL15: =IFERROR(F15/$E$3/1000/AK15,0) -> 0
A16: 999544 | C16: MIUDOS CONGELADOS DE FRANGO | D16: MIUDOS | E16: MOELA BDJ CG | F16: =SUMIF('COLAR PLANO'!$A:$A,A16,'COLAR PLANO'!$D:$D) -> 0 | G16: =IFERROR(F16/($E$3*$C$3),0) -> 0 | H16: 0.0106 | I16: =IFERROR(G16/$D$7/H16,0) -> 0 | J16: =IFERROR(I16/$B$7,0) -> 0 | K16: 0.45 | L16: 20 | M16: 9 | N16: =IFERROR(G16/K16,"-") -> 0 | P16: =IFERROR(G16/M16,"-") -> 0 | U16: - | V16: FRG | W16: =Preencher!$B$3&U16&V16&A16&$W$6 -> JARINU-FRG999544MQ.TUNEL DE CG (CONTINUO) | X16: =Preencher!$B$3&U16&V16&A16&$X$6 -> JARINU-FRG999544MQ.TUNEL DE CG (CONTINUO) (1) | Y16: =Preencher!$B$3&U16&V16&A16&$Y$6 -> JARINU-FRG999544MQ.TUNEL DE CG (CONTINUO) (2) | Z16: =Preencher!$B$3&U16&V16&A16&$Z$6 -> JARINU-FRG999544MQ.TUNEL DE CG (CONTINUO) (3) | AA16: =Preencher!$B$3&U16&V16&A16&$AA$6 -> JARINU-FRG999544MQ.TUNEL DE CG (ESTATICO) | AB16: =Preencher!$B$3&U16&V16&A16&$AB$6 -> JARINU-FRG999544MQ.TUNEL DE CG (ESTATICO) (1) | AC16: =Preencher!$B$3&U16&V16&A16&$AC$6 -> JARINU-FRG999544MQ.TUNEL DE CG (ESTATICO) (2) | AD16: =IFERROR(SUMIF('BD Otimix'!A:A,'BD VOLUME'!X16,'BD Otimix'!O:O)+SUMIF('BD Otimix'!A:A,'BD VOLUME'!Y16,'BD Otimix'!O:O)+SUMIF('BD Otimix'!A:A,'BD VOLUME'!Z16,'BD Otimix'!O:O)+SUMIF('BD Otimix'!A:A,'BD VOLUME'!AA16,'BD Otimix'!O:O)+SUMIF('BD Otimix'!A:A,'BD VOLUME'!AB16,'BD Otimix'!O:O)+SUMIF('BD Otimix'!A:A,'BD VOLUME'!AC16,'BD Otimix'!O:O)+SUMIF('BD Otimix'!A:A,'BD VOLUME'!W16,'BD Otimix'!O:O),0) -> 0 | AE16: =IFERROR(F16/$E$3/1000/AD16,0) -> 0 | AF16: =Preencher!$B$3&$U$8&$V$8&A16&$AF$6 -> JARINU-FRG999544MQ.GIROFREEZER | AG16: =Preencher!$B$3&$U$8&$V$8&A16&$AG$6 -> JARINU-FRG999544MQ.GIROFREEZER (1) | AH16: =Preencher!$B$3&$U$8&$V$8&A16&$AH$6 -> JARINU-FRG999544MQ.GIROFREEZER (2) | AI16: =Preencher!$B$3&$U$8&$V$8&A16&$AI$6 -> JARINU-FRG999544MQ.GIROFREEZER REV04 | AJ16: =Preencher!$B$3&$U$8&$V$8&A16&$AJ$6 -> JARINU-FRG999544MQ.GIROFREEZER (3) | AK16: =IFERROR(SUMIF('BD Otimix'!A:A,'BD VOLUME'!AG16,'BD Otimix'!O:O)+SUMIF('BD Otimix'!A:A,'BD VOLUME'!AH16,'BD Otimix'!O:O)+SUMIF('BD Otimix'!A:A,'BD VOLUME'!AI16,'BD Otimix'!O:O)+SUMIF('BD Otimix'!A:A,'BD VOLUME'!AJ16,'BD Otimix'!O:O)+SUMIF('BD Otimix'!A:A,'BD VOLUME'!AF16,'BD Otimix'!O:O),0) -> 0 | AL16: =IFERROR(F16/$E$3/1000/AK16,0) -> 0
A17: 12688 | C17: MOELA P/ REFEITORIO | D17: MIUDOS | E17: MOELA PACOTE 1 KG | F17: =SUMIF('COLAR PLANO'!$A:$A,A17,'COLAR PLANO'!$D:$D) -> 0 | G17: =IFERROR(F17/($E$3*$C$3),0) -> 0 | H17: 0.0106 | I17: =IFERROR(G17/$D$7/H17,0) -> 0 | J17: =IFERROR(I17/$B$7,0) -> 0 | K17: 1 | L17: 16 | M17: 16 | N17: =IFERROR(G17/K17,"-") -> 0 | P17: =IFERROR(G17/M17,"-") -> 0 | U17: - | V17: FRG | W17: =Preencher!$B$3&U17&V17&A17&$W$6 -> JARINU-FRG12688MQ.TUNEL DE CG (CONTINUO) | X17: =Preencher!$B$3&U17&V17&A17&$X$6 -> JARINU-FRG12688MQ.TUNEL DE CG (CONTINUO) (1) | Y17: =Preencher!$B$3&U17&V17&A17&$Y$6 -> JARINU-FRG12688MQ.TUNEL DE CG (CONTINUO) (2) | Z17: =Preencher!$B$3&U17&V17&A17&$Z$6 -> JARINU-FRG12688MQ.TUNEL DE CG (CONTINUO) (3) | AA17: =Preencher!$B$3&U17&V17&A17&$AA$6 -> JARINU-FRG12688MQ.TUNEL DE CG (ESTATICO) | AB17: =Preencher!$B$3&U17&V17&A17&$AB$6 -> JARINU-FRG12688MQ.TUNEL DE CG (ESTATICO) (1) | AC17: =Preencher!$B$3&U17&V17&A17&$AC$6 -> JARINU-FRG12688MQ.TUNEL DE CG (ESTATICO) (2) | AD17: =IFERROR(SUMIF('BD Otimix'!A:A,'BD VOLUME'!X17,'BD Otimix'!O:O)+SUMIF('BD Otimix'!A:A,'BD VOLUME'!Y17,'BD Otimix'!O:O)+SUMIF('BD Otimix'!A:A,'BD VOLUME'!Z17,'BD Otimix'!O:O)+SUMIF('BD Otimix'!A:A,'BD VOLUME'!AA17,'BD Otimix'!O:O)+SUMIF('BD Otimix'!A:A,'BD VOLUME'!AB17,'BD Otimix'!O:O)+SUMIF('BD Otimix'!A:A,'BD VOLUME'!AC17,'BD Otimix'!O:O)+SUMIF('BD Otimix'!A:A,'BD VOLUME'!W17,'BD Otimix'!O:O),0) -> 0 | AE17: =IFERROR(F17/$E$3/1000/AD17,0) -> 0 | AF17: =Preencher!$B$3&$U$8&$V$8&A17&$AF$6 -> JARINU-FRG12688MQ.GIROFREEZER | AG17: =Preencher!$B$3&$U$8&$V$8&A17&$AG$6 -> JARINU-FRG12688MQ.GIROFREEZER (1) | AH17: =Preencher!$B$3&$U$8&$V$8&A17&$AH$6 -> JARINU-FRG12688MQ.GIROFREEZER (2) | AI17: =Preencher!$B$3&$U$8&$V$8&A17&$AI$6 -> JARINU-FRG12688MQ.GIROFREEZER REV04 | AJ17: =Preencher!$B$3&$U$8&$V$8&A17&$AJ$6 -> JARINU-FRG12688MQ.GIROFREEZER (3) | AK17: =IFERROR(SUMIF('BD Otimix'!A:A,'BD VOLUME'!AG17,'BD Otimix'!O:O)+SUMIF('BD Otimix'!A:A,'BD VOLUME'!AH17,'BD Otimix'!O:O)+SUMIF('BD Otimix'!A:A,'BD VOLUME'!AI17,'BD Otimix'!O:O)+SUMIF('BD Otimix'!A:A,'BD VOLUME'!AJ17,'BD Otimix'!O:O)+SUMIF('BD Otimix'!A:A,'BD VOLUME'!AF17,'BD Otimix'!O:O),0) -> 0 | AL17: =IFERROR(F17/$E$3/1000/AK17,0) -> 0
A22: 997111 | C22: CORACAO CONG 18KG MP | D22: MIUDOS | E22: CORAÇÃO PACOTE 1 KG | F22: =SUMIF('COLAR PLANO'!$A:$A,A22,'COLAR PLANO'!$D:$D) -> 0 | G22: =IFERROR(F22/($E$3*$C$3),0) -> 0 | H22: 0.0047 | I22: =IFERROR(G22/$D$7/H22,0) -> 0 | J22: =IFERROR(I22/$B$7,0) -> 0 | K22: 1 | L22: 12 | M22: 12 | N22: =IFERROR(G22/K22,"-") -> 0 | P22: =IFERROR(G22/M22,"-") -> 0 | U22: - | V22: FRG | W22: =Preencher!$B$3&U22&V22&A22&$W$6 -> JARINU-FRG997111MQ.TUNEL DE CG (CONTINUO) | X22: =Preencher!$B$3&U22&V22&A22&$X$6 -> JARINU-FRG997111MQ.TUNEL DE CG (CONTINUO) (1) | Y22: =Preencher!$B$3&U22&V22&A22&$Y$6 -> JARINU-FRG997111MQ.TUNEL DE CG (CONTINUO) (2) | Z22: =Preencher!$B$3&U22&V22&A22&$Z$6 -> JARINU-FRG997111MQ.TUNEL DE CG (CONTINUO) (3) | AA22: =Preencher!$B$3&U22&V22&A22&$AA$6 -> JARINU-FRG997111MQ.TUNEL DE CG (ESTATICO) | AB22: =Preencher!$B$3&U22&V22&A22&$AB$6 -> JARINU-FRG997111MQ.TUNEL DE CG (ESTATICO) (1) | AC22: =Preencher!$B$3&U22&V22&A22&$AC$6 -> JARINU-FRG997111MQ.TUNEL DE CG (ESTATICO) (2) | AD22: =IFERROR(SUMIF('BD Otimix'!A:A,'BD VOLUME'!X22,'BD Otimix'!O:O)+SUMIF('BD Otimix'!A:A,'BD VOLUME'!Y22,'BD Otimix'!O:O)+SUMIF('BD Otimix'!A:A,'BD VOLUME'!Z22,'BD Otimix'!O:O)+SUMIF('BD Otimix'!A:A,'BD VOLUME'!AA22,'BD Otimix'!O:O)+SUMIF('BD Otimix'!A:A,'BD VOLUME'!AB22,'BD Otimix'!O:O)+SUMIF('BD Otimix'!A:A,'BD VOLUME'!AC22,'BD Otimix'!O:O)+SUMIF('BD Otimix'!A:A,'BD VOLUME'!W22,'BD Otimix'!O:O),0) -> 0 | AE22: =IFERROR(F22/$E$3/1000/AD22,0) -> 0 | AF22: =Preencher!$B$3&$U$8&$V$8&A22&$AF$6 -> JARINU-FRG997111MQ.GIROFREEZER | AG22: =Preencher!$B$3&$U$8&$V$8&A22&$AG$6 -> JARINU-FRG997111MQ.GIROFREEZER (1) | AH22: =Preencher!$B$3&$U$8&$V$8&A22&$AH$6 -> JARINU-FRG997111MQ.GIROFREEZER (2) | AI22: =Preencher!$B$3&$U$8&$V$8&A22&$AI$6 -> JARINU-FRG997111MQ.GIROFREEZER REV04 | AJ22: =Preencher!$B$3&$U$8&$V$8&A22&$AJ$6 -> JARINU-FRG997111MQ.GIROFREEZER (3) | AK22: =IFERROR(SUMIF('BD Otimix'!A:A,'BD VOLUME'!AG22,'BD Otimix'!O:O)+SUMIF('BD Otimix'!A:A,'BD VOLUME'!AH22,'BD Otimix'!O:O)+SUMIF('BD Otimix'!A:A,'BD VOLUME'!AI22,'BD Otimix'!O:O)+SUMIF('BD Otimix'!A:A,'BD VOLUME'!AJ22,'BD Otimix'!O:O)+SUMIF('BD Otimix'!A:A,'BD VOLUME'!AF22,'BD Otimix'!O:O),0) -> 0 | AL22: =IFERROR(F22/$E$3/1000/AK22,0) -> 0
A23: 18163 | C23: CORAÇÃO FGO CG ALM SE | D23: MIUDOS | E23: CORAÇÃO PACOTE 1 KG | F23: =SUMIF('COLAR PLANO'!$A:$A,A23,'COLAR PLANO'!$D:$D) -> 12096 | G23: =IFERROR(F23/($E$3*$C$3),0) -> 57.422264 | H23: 0.0047 | I23: =IFERROR(G23/$D$7/H23,0) -> 4072.501 | J23: =IFERROR(I23/$B$7,0) -> 0.86653772 | K23: 1 | L23: 12 | M23: 12 | N23: =IFERROR(G23/K23,"-") -> 57.422264 | P23: =IFERROR(G23/M23,"-") -> 4.7851887 | U23: - | V23: FRG | W23: =Preencher!$B$3&U23&V23&A23&$W$6 -> JARINU-FRG18163MQ.TUNEL DE CG (CONTINUO) | X23: =Preencher!$B$3&U23&V23&A23&$X$6 -> JARINU-FRG18163MQ.TUNEL DE CG (CONTINUO) (1) | Y23: =Preencher!$B$3&U23&V23&A23&$Y$6 -> JARINU-FRG18163MQ.TUNEL DE CG (CONTINUO) (2) | Z23: =Preencher!$B$3&U23&V23&A23&$Z$6 -> JARINU-FRG18163MQ.TUNEL DE CG (CONTINUO) (3) | AA23: =Preencher!$B$3&U23&V23&A23&$AA$6 -> JARINU-FRG18163MQ.TUNEL DE CG (ESTATICO) | AB23: =Preencher!$B$3&U23&V23&A23&$AB$6 -> JARINU-FRG18163MQ.TUNEL DE CG (ESTATICO) (1) | AC23: =Preencher!$B$3&U23&V23&A23&$AC$6 -> JARINU-FRG18163MQ.TUNEL DE CG (ESTATICO) (2) | AD23: =IFERROR(SUMIF('BD Otimix'!A:A,'BD VOLUME'!X23,'BD Otimix'!O:O)+SUMIF('BD Otimix'!A:A,'BD VOLUME'!Y23,'BD Otimix'!O:O)+SUMIF('BD Otimix'!A:A,'BD VOLUME'!Z23,'BD Otimix'!O:O)+SUMIF('BD Otimix'!A:A,'BD VOLUME'!AA23,'BD Otimix'!O:O)+SUMIF('BD Otimix'!A:A,'BD VOLUME'!AB23,'BD Otimix'!O:O)+SUMIF('BD Otimix'!A:A,'BD VOLUME'!AC23,'BD Otimix'!O:O)+SUMIF('BD Otimix'!A:A,'BD VOLUME'!W23,'BD Otimix'!O:O),0) -> 0 | AE23: =IFERROR(F23/$E$3/1000/AD23,0) -> 0 | AF23: =Preencher!$B$3&$U$8&$V$8&A23&$AF$6 -> JARINU-FRG18163MQ.GIROFREEZER | AG23: =Preencher!$B$3&$U$8&$V$8&A23&$AG$6 -> JARINU-FRG18163MQ.GIROFREEZER (1) | AH23: =Preencher!$B$3&$U$8&$V$8&A23&$AH$6 -> JARINU-FRG18163MQ.GIROFREEZER (2) | AI23: =Preencher!$B$3&$U$8&$V$8&A23&$AI$6 -> JARINU-FRG18163MQ.GIROFREEZER REV04 | AJ23: =Preencher!$B$3&$U$8&$V$8&A23&$AJ$6 -> JARINU-FRG18163MQ.GIROFREEZER (3) | AK23: =IFERROR(SUMIF('BD Otimix'!A:A,'BD VOLUME'!AG23,'BD Otimix'!O:O)+SUMIF('BD Otimix'!A:A,'BD VOLUME'!AH23,'BD Otimix'!O:O)+SUMIF('BD Otimix'!A:A,'BD VOLUME'!AI23,'BD Otimix'!O:O)+SUMIF('BD Otimix'!A:A,'BD VOLUME'!AJ23,'BD Otimix'!O:O)+SUMIF('BD Otimix'!A:A,'BD VOLUME'!AF23,'BD Otimix'!O:O),0) -> 0 | AL23: =IFERROR(F23/$E$3/1000/AK23,0) -> 0
A24: 15423 | B24: COR-BJ | C24: CORACAO FGO CG BDJ SE | D24: MIUDOS | E24: CORAÇÃO BDJ CG | F24: =SUMIF('COLAR PLANO'!$A:$A,A24,'COLAR PLANO'!$D:$D) -> 0 | G24: =IFERROR(F24/($E$3*$C$3),0) -> 0 | H24: 0.0047 | I24: =IFERROR(G24/$D$7/H24,0) -> 0 | J24: =IFERROR(I24/$B$7,0) -> 0 | K24: 0.45 | L24: 16 | M24: 9 | N24: =IFERROR(G24/K24,"-") -> 0 | P24: =IFERROR(G24/M24,"-") -> 0 | U24: - | V24: FRG | W24: =Preencher!$B$3&U24&V24&A24&$W$6 -> JARINU-FRG15423MQ.TUNEL DE CG (CONTINUO) | X24: =Preencher!$B$3&U24&V24&A24&$X$6 -> JARINU-FRG15423MQ.TUNEL DE CG (CONTINUO) (1) | Y24: =Preencher!$B$3&U24&V24&A24&$Y$6 -> JARINU-FRG15423MQ.TUNEL DE CG (CONTINUO) (2) | Z24: =Preencher!$B$3&U24&V24&A24&$Z$6 -> JARINU-FRG15423MQ.TUNEL DE CG (CONTINUO) (3) | AA24: =Preencher!$B$3&U24&V24&A24&$AA$6 -> JARINU-FRG15423MQ.TUNEL DE CG (ESTATICO) | AB24: =Preencher!$B$3&U24&V24&A24&$AB$6 -> JARINU-FRG15423MQ.TUNEL DE CG (ESTATICO) (1) | AC24: =Preencher!$B$3&U24&V24&A24&$AC$6 -> JARINU-FRG15423MQ.TUNEL DE CG (ESTATICO) (2) | AD24: =IFERROR(SUMIF('BD Otimix'!A:A,'BD VOLUME'!X24,'BD Otimix'!O:O)+SUMIF('BD Otimix'!A:A,'BD VOLUME'!Y24,'BD Otimix'!O:O)+SUMIF('BD Otimix'!A:A,'BD VOLUME'!Z24,'BD Otimix'!O:O)+SUMIF('BD Otimix'!A:A,'BD VOLUME'!AA24,'BD Otimix'!O:O)+SUMIF('BD Otimix'!A:A,'BD VOLUME'!AB24,'BD Otimix'!O:O)+SUMIF('BD Otimix'!A:A,'BD VOLUME'!AC24,'BD Otimix'!O:O)+SUMIF('BD Otimix'!A:A,'BD VOLUME'!W24,'BD Otimix'!O:O),0) -> 0 | AE24: =IFERROR(F24/$E$3/1000/AD24,0) -> 0 | AF24: =Preencher!$B$3&$U$8&$V$8&A24&$AF$6 -> JARINU-FRG15423MQ.GIROFREEZER | AG24: =Preencher!$B$3&$U$8&$V$8&A24&$AG$6 -> JARINU-FRG15423MQ.GIROFREEZER (1) | AH24: =Preencher!$B$3&$U$8&$V$8&A24&$AH$6 -> JARINU-FRG15423MQ.GIROFREEZER (2) | AI24: =Preencher!$B$3&$U$8&$V$8&A24&$AI$6 -> JARINU-FRG15423MQ.GIROFREEZER REV04 | AJ24: =Preencher!$B$3&$U$8&$V$8&A24&$AJ$6 -> JARINU-FRG15423MQ.GIROFREEZER (3) | AK24: =IFERROR(SUMIF('BD Otimix'!A:A,'BD VOLUME'!AG24,'BD Otimix'!O:O)+SUMIF('BD Otimix'!A:A,'BD VOLUME'!AH24,'BD Otimix'!O:O)+SUMIF('BD Otimix'!A:A,'BD VOLUME'!AI24,'BD Otimix'!O:O)+SUMIF('BD Otimix'!A:A,'BD VOLUME'!AJ24,'BD Otimix'!O:O)+SUMIF('BD Otimix'!A:A,'BD VOLUME'!AF24,'BD Otimix'!O:O),0) -> 0 | AL24: =IFERROR(F24/$E$3/1000/AK24,0) -> 0
A25: 729850 | B25: COR-01 | C25: CORACAO FGO RESF BDJ SE | D25: MIUDOS | E25: CORAÇÃO BDJ RF | F25: =SUMIF('COLAR PLANO'!$A:$A,A25,'COLAR PLANO'!$D:$D) -> 0 | G25: =IFERROR(F25/($E$3*$C$3),0) -> 0 | H25: 0.0047 | I25: =IFERROR(G25/$D$7/H25,0) -> 0 | J25: =IFERROR(I25/$B$7,0) -> 0 | K25: 0.65 | L25: 10 | M25: 6.5 | N25: =IFERROR(G25/K25,"-") -> 0 | P25: =IFERROR(G25/M25,"-") -> 0 | U25: - | V25: FRG | W25: =Preencher!$B$3&U25&V25&A25&$W$6 -> JARINU-FRG729850MQ.TUNEL DE CG (CONTINUO) | X25: =Preencher!$B$3&U25&V25&A25&$X$6 -> JARINU-FRG729850MQ.TUNEL DE CG (CONTINUO) (1) | Y25: =Preencher!$B$3&U25&V25&A25&$Y$6 -> JARINU-FRG729850MQ.TUNEL DE CG (CONTINUO) (2) | Z25: =Preencher!$B$3&U25&V25&A25&$Z$6 -> JARINU-FRG729850MQ.TUNEL DE CG (CONTINUO) (3) | AA25: =Preencher!$B$3&U25&V25&A25&$AA$6 -> JARINU-FRG729850MQ.TUNEL DE CG (ESTATICO) | AB25: =Preencher!$B$3&U25&V25&A25&$AB$6 -> JARINU-FRG729850MQ.TUNEL DE CG (ESTATICO) (1) | AC25: =Preencher!$B$3&U25&V25&A25&$AC$6 -> JARINU-FRG729850MQ.TUNEL DE CG (ESTATICO) (2) | AD25: =IFERROR(SUMIF('BD Otimix'!A:A,'BD VOLUME'!X25,'BD Otimix'!O:O)+SUMIF('BD Otimix'!A:A,'BD VOLUME'!Y25,'BD Otimix'!O:O)+SUMIF('BD Otimix'!A:A,'BD VOLUME'!Z25,'BD Otimix'!O:O)+SUMIF('BD Otimix'!A:A,'BD VOLUME'!AA25,'BD Otimix'!O:O)+SUMIF('BD Otimix'!A:A,'BD VOLUME'!AB25,'BD Otimix'!O:O)+SUMIF('BD Otimix'!A:A,'BD VOLUME'!AC25,'BD Otimix'!O:O)+SUMIF('BD Otimix'!A:A,'BD VOLUME'!W25,'BD Otimix'!O:O),0) -> 0 | AE25: =IFERROR(F25/$E$3/1000/AD25,0) -> 0 | AF25: =Preencher!$B$3&$U$8&$V$8&A25&$AF$6 -> JARINU-FRG729850MQ.GIROFREEZER | AG25: =Preencher!$B$3&$U$8&$V$8&A25&$AG$6 -> JARINU-FRG729850MQ.GIROFREEZER (1) | AH25: =Preencher!$B$3&$U$8&$V$8&A25&$AH$6 -> JARINU-FRG729850MQ.GIROFREEZER (2) | AI25: =Preencher!$B$3&$U$8&$V$8&A25&$AI$6 -> JARINU-FRG729850MQ.GIROFREEZER REV04 | AJ25: =Preencher!$B$3&$U$8&$V$8&A25&$AJ$6 -> JARINU-FRG729850MQ.GIROFREEZER (3) | AK25: =IFERROR(SUMIF('BD Otimix'!A:A,'BD VOLUME'!AG25,'BD Otimix'!O:O)+SUMIF('BD Otimix'!A:A,'BD VOLUME'!AH25,'BD Otimix'!O:O)+SUMIF('BD Otimix'!A:A,'BD VOLUME'!AI25,'BD Otimix'!O:O)+SUMIF('BD Otimix'!A:A,'BD VOLUME'!AJ25,'BD Otimix'!O:O)+SUMIF('BD Otimix'!A:A,'BD VOLUME'!AF25,'BD Otimix'!O:O),0) -> 0 | AL25: =IFERROR(F25/$E$3/1000/AK25,0) -> 0
A26: 956767 | C26: MIUDOS CG FG CORACAO BDJ 1KG | D26: MIUDOS | E26: CORAÇÃO BDJ CG | F26: =SUMIF('COLAR PLANO'!$A:$A,A26,'COLAR PLANO'!$D:$D) -> 0 | G26: =IFERROR(F26/($E$3*$C$3),0) -> 0 | H26: 0.0047 | I26: =IFERROR(G26/$D$7/H26,0) -> 0 | J26: =IFERROR(I26/$B$7,0) -> 0 | K26: 1 | L26: 12 | M26: 12 | N26: =IFERROR(G26/K26,"-") -> 0 | P26: =IFERROR(G26/M26,"-") -> 0 | U26: - | V26: FRG | W26: =Preencher!$B$3&U26&V26&A26&$W$6 -> JARINU-FRG956767MQ.TUNEL DE CG (CONTINUO) | X26: =Preencher!$B$3&U26&V26&A26&$X$6 -> JARINU-FRG956767MQ.TUNEL DE CG (CONTINUO) (1) | Y26: =Preencher!$B$3&U26&V26&A26&$Y$6 -> JARINU-FRG956767MQ.TUNEL DE CG (CONTINUO) (2) | Z26: =Preencher!$B$3&U26&V26&A26&$Z$6 -> JARINU-FRG956767MQ.TUNEL DE CG (CONTINUO) (3) | AA26: =Preencher!$B$3&U26&V26&A26&$AA$6 -> JARINU-FRG956767MQ.TUNEL DE CG (ESTATICO) | AB26: =Preencher!$B$3&U26&V26&A26&$AB$6 -> JARINU-FRG956767MQ.TUNEL DE CG (ESTATICO) (1) | AC26: =Preencher!$B$3&U26&V26&A26&$AC$6 -> JARINU-FRG956767MQ.TUNEL DE CG (ESTATICO) (2) | AD26: =IFERROR(SUMIF('BD Otimix'!A:A,'BD VOLUME'!X26,'BD Otimix'!O:O)+SUMIF('BD Otimix'!A:A,'BD VOLUME'!Y26,'BD Otimix'!O:O)+SUMIF('BD Otimix'!A:A,'BD VOLUME'!Z26,'BD Otimix'!O:O)+SUMIF('BD Otimix'!A:A,'BD VOLUME'!AA26,'BD Otimix'!O:O)+SUMIF('BD Otimix'!A:A,'BD VOLUME'!AB26,'BD Otimix'!O:O)+SUMIF('BD Otimix'!A:A,'BD VOLUME'!AC26,'BD Otimix'!O:O)+SUMIF('BD Otimix'!A:A,'BD VOLUME'!W26,'BD Otimix'!O:O),0) -> 0 | AE26: =IFERROR(F26/$E$3/1000/AD26,0) -> 0 | AF26: =Preencher!$B$3&$U$8&$V$8&A26&$AF$6 -> JARINU-FRG956767MQ.GIROFREEZER | AG26: =Preencher!$B$3&$U$8&$V$8&A26&$AG$6 -> JARINU-FRG956767MQ.GIROFREEZER (1) | AH26: =Preencher!$B$3&$U$8&$V$8&A26&$AH$6 -> JARINU-FRG956767MQ.GIROFREEZER (2) | AI26: =Preencher!$B$3&$U$8&$V$8&A26&$AI$6 -> JARINU-FRG956767MQ.GIROFREEZER REV04 | AJ26: =Preencher!$B$3&$U$8&$V$8&A26&$AJ$6 -> JARINU-FRG956767MQ.GIROFREEZER (3) | AK26: =IFERROR(SUMIF('BD Otimix'!A:A,'BD VOLUME'!AG26,'BD Otimix'!O:O)+SUMIF('BD Otimix'!A:A,'BD VOLUME'!AH26,'BD Otimix'!O:O)+SUMIF('BD Otimix'!A:A,'BD VOLUME'!AI26,'BD Otimix'!O:O)+SUMIF('BD Otimix'!A:A,'BD VOLUME'!AJ26,'BD Otimix'!O:O)+SUMIF('BD Otimix'!A:A,'BD VOLUME'!AF26,'BD Otimix'!O:O),0) -> 0 | AL26: =IFERROR(F26/$E$3/1000/AK26,0) -> 0
A27: 124462 | B27: tmf | C27: MIUDOS TEMP RESF FG CORACAO | D27: MIUDOS | E27: CORAÇÃO BDJ CG | F27: =SUMIF('COLAR PLANO'!$A:$A,A27,'COLAR PLANO'!$D:$D) -> 0 | G27: =IFERROR(F27/($E$3*$C$3),0) -> 0 | H27: 0.0047 | I27: =IFERROR(G27/$D$7/H27,0) -> 0 | J27: =IFERROR(I27/$B$7,0) -> 0 | K27: 1 | L27: 12 | M27: 12 | N27: =IFERROR(G27/K27,"-") -> 0 | P27: =IFERROR(G27/M27,"-") -> 0 | U27: - | V27: FRG | W27: =Preencher!$B$3&U27&V27&A27&$W$6 -> JARINU-FRG124462MQ.TUNEL DE CG (CONTINUO) | X27: =Preencher!$B$3&U27&V27&A27&$X$6 -> JARINU-FRG124462MQ.TUNEL DE CG (CONTINUO) (1) | Y27: =Preencher!$B$3&U27&V27&A27&$Y$6 -> JARINU-FRG124462MQ.TUNEL DE CG (CONTINUO) (2) | Z27: =Preencher!$B$3&U27&V27&A27&$Z$6 -> JARINU-FRG124462MQ.TUNEL DE CG (CONTINUO) (3) | AA27: =Preencher!$B$3&U27&V27&A27&$AA$6 -> JARINU-FRG124462MQ.TUNEL DE CG (ESTATICO) | AB27: =Preencher!$B$3&U27&V27&A27&$AB$6 -> JARINU-FRG124462MQ.TUNEL DE CG (ESTATICO) (1) | AC27: =Preencher!$B$3&U27&V27&A27&$AC$6 -> JARINU-FRG124462MQ.TUNEL DE CG (ESTATICO) (2) | AD27: =IFERROR(SUMIF('BD Otimix'!A:A,'BD VOLUME'!X27,'BD Otimix'!O:O)+SUMIF('BD Otimix'!A:A,'BD VOLUME'!Y27,'BD Otimix'!O:O)+SUMIF('BD Otimix'!A:A,'BD VOLUME'!Z27,'BD Otimix'!O:O)+SUMIF('BD Otimix'!A:A,'BD VOLUME'!AA27,'BD Otimix'!O:O)+SUMIF('BD Otimix'!A:A,'BD VOLUME'!AB27,'BD Otimix'!O:O)+SUMIF('BD Otimix'!A:A,'BD VOLUME'!AC27,'BD Otimix'!O:O)+SUMIF('BD Otimix'!A:A,'BD VOLUME'!W27,'BD Otimix'!O:O),0) -> 0 | AE27: =IFERROR(F27/$E$3/1000/AD27,0) -> 0 | AF27: =Preencher!$B$3&$U$8&$V$8&A27&$AF$6 -> JARINU-FRG124462MQ.GIROFREEZER | AG27: =Preencher!$B$3&$U$8&$V$8&A27&$AG$6 -> JARINU-FRG124462MQ.GIROFREEZER (1) | AH27: =Preencher!$B$3&$U$8&$V$8&A27&$AH$6 -> JARINU-FRG124462MQ.GIROFREEZER (2) | AI27: =Preencher!$B$3&$U$8&$V$8&A27&$AI$6 -> JARINU-FRG124462MQ.GIROFREEZER REV04 | AJ27: =Preencher!$B$3&$U$8&$V$8&A27&$AJ$6 -> JARINU-FRG124462MQ.GIROFREEZER (3) | AK27: =IFERROR(SUMIF('BD Otimix'!A:A,'BD VOLUME'!AG27,'BD Otimix'!O:O)+SUMIF('BD Otimix'!A:A,'BD VOLUME'!AH27,'BD Otimix'!O:O)+SUMIF('BD Otimix'!A:A,'BD VOLUME'!AI27,'BD Otimix'!O:O)+SUMIF('BD Otimix'!A:A,'BD VOLUME'!AJ27,'BD Otimix'!O:O)+SUMIF('BD Otimix'!A:A,'BD VOLUME'!AF27,'BD Otimix'!O:O),0) -> 0 | AL27: =IFERROR(F27/$E$3/1000/AK27,0) -> 0
A28: 124369 | C28: MIUDOS CG FG TEMP CORACAO BD | D28: MIUDOS | E28: CORAÇÃO BDJ CG | F28: =SUMIF('COLAR PLANO'!$A:$A,A28,'COLAR PLANO'!$D:$D) -> 0 | G28: =IFERROR(F28/($E$3*$C$3),0) -> 0 | H28: 0.0047 | I28: =IFERROR(G28/$D$7/H28,0) -> 0 | J28: =IFERROR(I28/$B$7,0) -> 0 | K28: 1 | L28: 12 | M28: 12 | N28: =IFERROR(G28/K28,"-") -> 0 | P28: =IFERROR(G28/M28,"-") -> 0 | U28: - | V28: FRG | W28: =Preencher!$B$3&U28&V28&A28&$W$6 -> JARINU-FRG124369MQ.TUNEL DE CG (CONTINUO) | X28: =Preencher!$B$3&U28&V28&A28&$X$6 -> JARINU-FRG124369MQ.TUNEL DE CG (CONTINUO) (1) | Y28: =Preencher!$B$3&U28&V28&A28&$Y$6 -> JARINU-FRG124369MQ.TUNEL DE CG (CONTINUO) (2) | Z28: =Preencher!$B$3&U28&V28&A28&$Z$6 -> JARINU-FRG124369MQ.TUNEL DE CG (CONTINUO) (3) | AA28: =Preencher!$B$3&U28&V28&A28&$AA$6 -> JARINU-FRG124369MQ.TUNEL DE CG (ESTATICO) | AB28: =Preencher!$B$3&U28&V28&A28&$AB$6 -> JARINU-FRG124369MQ.TUNEL DE CG (ESTATICO) (1) | AC28: =Preencher!$B$3&U28&V28&A28&$AC$6 -> JARINU-FRG124369MQ.TUNEL DE CG (ESTATICO) (2) | AD28: =IFERROR(SUMIF('BD Otimix'!A:A,'BD VOLUME'!X28,'BD Otimix'!O:O)+SUMIF('BD Otimix'!A:A,'BD VOLUME'!Y28,'BD Otimix'!O:O)+SUMIF('BD Otimix'!A:A,'BD VOLUME'!Z28,'BD Otimix'!O:O)+SUMIF('BD Otimix'!A:A,'BD VOLUME'!AA28,'BD Otimix'!O:O)+SUMIF('BD Otimix'!A:A,'BD VOLUME'!AB28,'BD Otimix'!O:O)+SUMIF('BD Otimix'!A:A,'BD VOLUME'!AC28,'BD Otimix'!O:O)+SUMIF('BD Otimix'!A:A,'BD VOLUME'!W28,'BD Otimix'!O:O),0) -> 0 | AE28: =IFERROR(F28/$E$3/1000/AD28,0) -> 0 | AF28: =Preencher!$B$3&$U$8&$V$8&A28&$AF$6 -> JARINU-FRG124369MQ.GIROFREEZER | AG28: =Preencher!$B$3&$U$8&$V$8&A28&$AG$6 -> JARINU-FRG124369MQ.GIROFREEZER (1) | AH28: =Preencher!$B$3&$U$8&$V$8&A28&$AH$6 -> JARINU-FRG124369MQ.GIROFREEZER (2) | AI28: =Preencher!$B$3&$U$8&$V$8&A28&$AI$6 -> JARINU-FRG124369MQ.GIROFREEZER REV04 | AJ28: =Preencher!$B$3&$U$8&$V$8&A28&$AJ$6 -> JARINU-FRG124369MQ.GIROFREEZER (3) | AK28: =IFERROR(SUMIF('BD Otimix'!A:A,'BD VOLUME'!AG28,'BD Otimix'!O:O)+SUMIF('BD Otimix'!A:A,'BD VOLUME'!AH28,'BD Otimix'!O:O)+SUMIF('BD Otimix'!A:A,'BD VOLUME'!AI28,'BD Otimix'!O:O)+SUMIF('BD Otimix'!A:A,'BD VOLUME'!AJ28,'BD Otimix'!O:O)+SUMIF('BD Otimix'!A:A,'BD VOLUME'!AF28,'BD Otimix'!O:O),0) -> 0 | AL28: =IFERROR(F28/$E$3/1000/AK28,0) -> 0
A29: 124006 | C29: CORACAO FGO (C) BDJ 12X1KG | D29: MIUDOS | E29: CORAÇÃO BDJ CG | F29: =SUMIF('COLAR PLANO'!$A:$A,A29,'COLAR PLANO'!$D:$D) -> 0 | G29: =IFERROR(F29/($E$3*$C$3),0) -> 0 | H29: 0.0047 | I29: =IFERROR(G29/$D$7/H29,0) -> 0 | J29: =IFERROR(I29/$B$7,0) -> 0 | K29: 1 | L29: 12 | M29: 12 | N29: =IFERROR(G29/K29,"-") -> 0 | P29: =IFERROR(G29/M29,"-") -> 0 | U29: - | V29: FRG | W29: =Preencher!$B$3&U29&V29&A29&$W$6 -> JARINU-FRG124006MQ.TUNEL DE CG (CONTINUO) | X29: =Preencher!$B$3&U29&V29&A29&$X$6 -> JARINU-FRG124006MQ.TUNEL DE CG (CONTINUO) (1) | Y29: =Preencher!$B$3&U29&V29&A29&$Y$6 -> JARINU-FRG124006MQ.TUNEL DE CG (CONTINUO) (2) | Z29: =Preencher!$B$3&U29&V29&A29&$Z$6 -> JARINU-FRG124006MQ.TUNEL DE CG (CONTINUO) (3) | AA29: =Preencher!$B$3&U29&V29&A29&$AA$6 -> JARINU-FRG124006MQ.TUNEL DE CG (ESTATICO) | AB29: =Preencher!$B$3&U29&V29&A29&$AB$6 -> JARINU-FRG124006MQ.TUNEL DE CG (ESTATICO) (1) | AC29: =Preencher!$B$3&U29&V29&A29&$AC$6 -> JARINU-FRG124006MQ.TUNEL DE CG (ESTATICO) (2) | AD29: =IFERROR(SUMIF('BD Otimix'!A:A,'BD VOLUME'!X29,'BD Otimix'!O:O)+SUMIF('BD Otimix'!A:A,'BD VOLUME'!Y29,'BD Otimix'!O:O)+SUMIF('BD Otimix'!A:A,'BD VOLUME'!Z29,'BD Otimix'!O:O)+SUMIF('BD Otimix'!A:A,'BD VOLUME'!AA29,'BD Otimix'!O:O)+SUMIF('BD Otimix'!A:A,'BD VOLUME'!AB29,'BD Otimix'!O:O)+SUMIF('BD Otimix'!A:A,'BD VOLUME'!AC29,'BD Otimix'!O:O)+SUMIF('BD Otimix'!A:A,'BD VOLUME'!W29,'BD Otimix'!O:O),0) -> 0 | AE29: =IFERROR(F29/$E$3/1000/AD29,0) -> 0 | AF29: =Preencher!$B$3&$U$8&$V$8&A29&$AF$6 -> JARINU-FRG124006MQ.GIROFREEZER | AG29: =Preencher!$B$3&$U$8&$V$8&A29&$AG$6 -> JARINU-FRG124006MQ.GIROFREEZER (1) | AH29: =Preencher!$B$3&$U$8&$V$8&A29&$AH$6 -> JARINU-FRG124006MQ.GIROFREEZER (2) | AI29: =Preencher!$B$3&$U$8&$V$8&A29&$AI$6 -> JARINU-FRG124006MQ.GIROFREEZER REV04 | AJ29: =Preencher!$B$3&$U$8&$V$8&A29&$AJ$6 -> JARINU-FRG124006MQ.GIROFREEZER (3) | AK29: =IFERROR(SUMIF('BD Otimix'!A:A,'BD VOLUME'!AG29,'BD Otimix'!O:O)+SUMIF('BD Otimix'!A:A,'BD VOLUME'!AH29,'BD Otimix'!O:O)+SUMIF('BD Otimix'!A:A,'BD VOLUME'!AI29,'BD Otimix'!O:O)+SUMIF('BD Otimix'!A:A,'BD VOLUME'!AJ29,'BD Otimix'!O:O)+SUMIF('BD Otimix'!A:A,'BD VOLUME'!AF29,'BD Otimix'!O:O),0) -> 0 | AL29: =IFERROR(F29/$E$3/1000/AK29,0) -> 0
D30: MIUDOS | E30: Fígado Pacote 0,45 Kg | F30: =SUMIF('COLAR PLANO'!$A:$A,A30,'COLAR PLANO'!$D:$D) -> 0 | G30: =IFERROR(F30/($E$3*$C$3),0) -> 0 | H30: 0.0175 | I30: =IFERROR(G30/$D$7/H30,0) -> 0 | J30: =IFERROR(I30/$B$7,0) -> 0 | K30: 0.5 | L30: 24 | M30: 12 | N30: =IFERROR(G30/K30,"-") -> 0 | P30: =IFERROR(G30/M30,"-") -> 0 | U30: - | V30: FRG | W30: =Preencher!$B$3&U30&V30&A30&$W$6 -> JARINU-FRGMQ.TUNEL DE CG (CONTINUO) | X30: =Preencher!$B$3&U30&V30&A30&$X$6 -> JARINU-FRGMQ.TUNEL DE CG (CONTINUO) (1) | Y30: =Preencher!$B$3&U30&V30&A30&$Y$6 -> JARINU-FRGMQ.TUNEL DE CG (CONTINUO) (2) | Z30: =Preencher!$B$3&U30&V30&A30&$Z$6 -> JARINU-FRGMQ.TUNEL DE CG (CONTINUO) (3) | AA30: =Preencher!$B$3&U30&V30&A30&$AA$6 -> JARINU-FRGMQ.TUNEL DE CG (ESTATICO) | AB30: =Preencher!$B$3&U30&V30&A30&$AB$6 -> JARINU-FRGMQ.TUNEL DE CG (ESTATICO) (1) | AC30: =Preencher!$B$3&U30&V30&A30&$AC$6 -> JARINU-FRGMQ.TUNEL DE CG (ESTATICO) (2) | AD30: =IFERROR(SUMIF('BD Otimix'!A:A,'BD VOLUME'!X30,'BD Otimix'!O:O)+SUMIF('BD Otimix'!A:A,'BD VOLUME'!Y30,'BD Otimix'!O:O)+SUMIF('BD Otimix'!A:A,'BD VOLUME'!Z30,'BD Otimix'!O:O)+SUMIF('BD Otimix'!A:A,'BD VOLUME'!AA30,'BD Otimix'!O:O)+SUMIF('BD Otimix'!A:A,'BD VOLUME'!AB30,'BD Otimix'!O:O)+SUMIF('BD Otimix'!A:A,'BD VOLUME'!AC30,'BD Otimix'!O:O)+SUMIF('BD Otimix'!A:A,'BD VOLUME'!W30,'BD Otimix'!O:O),0) -> 0 | AE30: =IFERROR(F30/$E$3/1000/AD30,0) -> 0 | AF30: =Preencher!$B$3&$U$8&$V$8&A30&$AF$6 -> JARINU-FRGMQ.GIROFREEZER | AG30: =Preencher!$B$3&$U$8&$V$8&A30&$AG$6 -> JARINU-FRGMQ.GIROFREEZER (1) | AH30: =Preencher!$B$3&$U$8&$V$8&A30&$AH$6 -> JARINU-FRGMQ.GIROFREEZER (2) | AI30: =Preencher!$B$3&$U$8&$V$8&A30&$AI$6 -> JARINU-FRGMQ.GIROFREEZER REV04 | AJ30: =Preencher!$B$3&$U$8&$V$8&A30&$AJ$6 -> JARINU-FRGMQ.GIROFREEZER (3) | AK30: =IFERROR(SUMIF('BD Otimix'!A:A,'BD VOLUME'!AG30,'BD Otimix'!O:O)+SUMIF('BD Otimix'!A:A,'BD VOLUME'!AH30,'BD Otimix'!O:O)+SUMIF('BD Otimix'!A:A,'BD VOLUME'!AI30,'BD Otimix'!O:O)+SUMIF('BD Otimix'!A:A,'BD VOLUME'!AJ30,'BD Otimix'!O:O)+SUMIF('BD Otimix'!A:A,'BD VOLUME'!AF30,'BD Otimix'!O:O),0) -> 0 | AL30: =IFERROR(F30/$E$3/1000/AK30,0) -> 0
A31: 729876 | B31: FIG-01 | C31: FIGADO FGO RESF BDJ SEARA | D31: MIUDOS | E31: Fígado BDJ RF | F31: =SUMIF('COLAR PLANO'!$A:$A,A31,'COLAR PLANO'!$D:$D) -> 0 | G31: =IFERROR(F31/($E$3*$C$3),0) -> 0 | H31: 0.0175 | I31: =IFERROR(G31/$D$7/H31,0) -> 0 | J31: =IFERROR(I31/$B$7,0) -> 0 | K31: 1 | L31: 12 | M31: 12 | N31: =IFERROR(G31/K31,"-") -> 0 | P31: =IFERROR(G31/M31,"-") -> 0 | U31: - | V31: FRG | W31: =Preencher!$B$3&U31&V31&A31&$W$6 -> JARINU-FRG729876MQ.TUNEL DE CG (CONTINUO) | X31: =Preencher!$B$3&U31&V31&A31&$X$6 -> JARINU-FRG729876MQ.TUNEL DE CG (CONTINUO) (1) | Y31: =Preencher!$B$3&U31&V31&A31&$Y$6 -> JARINU-FRG729876MQ.TUNEL DE CG (CONTINUO) (2) | Z31: =Preencher!$B$3&U31&V31&A31&$Z$6 -> JARINU-FRG729876MQ.TUNEL DE CG (CONTINUO) (3) | AA31: =Preencher!$B$3&U31&V31&A31&$AA$6 -> JARINU-FRG729876MQ.TUNEL DE CG (ESTATICO) | AB31: =Preencher!$B$3&U31&V31&A31&$AB$6 -> JARINU-FRG729876MQ.TUNEL DE CG (ESTATICO) (1) | AC31: =Preencher!$B$3&U31&V31&A31&$AC$6 -> JARINU-FRG729876MQ.TUNEL DE CG (ESTATICO) (2) | AD31: =IFERROR(SUMIF('BD Otimix'!A:A,'BD VOLUME'!X31,'BD Otimix'!O:O)+SUMIF('BD Otimix'!A:A,'BD VOLUME'!Y31,'BD Otimix'!O:O)+SUMIF('BD Otimix'!A:A,'BD VOLUME'!Z31,'BD Otimix'!O:O)+SUMIF('BD Otimix'!A:A,'BD VOLUME'!AA31,'BD Otimix'!O:O)+SUMIF('BD Otimix'!A:A,'BD VOLUME'!AB31,'BD Otimix'!O:O)+SUMIF('BD Otimix'!A:A,'BD VOLUME'!AC31,'BD Otimix'!O:O)+SUMIF('BD Otimix'!A:A,'BD VOLUME'!W31,'BD Otimix'!O:O),0) -> 0 | AE31: =IFERROR(F31/$E$3/1000/AD31,0) -> 0 | AF31: =Preencher!$B$3&$U$8&$V$8&A31&$AF$6 -> JARINU-FRG729876MQ.GIROFREEZER | AG31: =Preencher!$B$3&$U$8&$V$8&A31&$AG$6 -> JARINU-FRG729876MQ.GIROFREEZER (1) | AH31: =Preencher!$B$3&$U$8&$V$8&A31&$AH$6 -> JARINU-FRG729876MQ.GIROFREEZER (2) | AI31: =Preencher!$B$3&$U$8&$V$8&A31&$AI$6 -> JARINU-FRG729876MQ.GIROFREEZER REV04 | AJ31: =Preencher!$B$3&$U$8&$V$8&A31&$AJ$6 -> JARINU-FRG729876MQ.GIROFREEZER (3) | AK31: =IFERROR(SUMIF('BD Otimix'!A:A,'BD VOLUME'!AG31,'BD Otimix'!O:O)+SUMIF('BD Otimix'!A:A,'BD VOLUME'!AH31,'BD Otimix'!O:O)+SUMIF('BD Otimix'!A:A,'BD VOLUME'!AI31,'BD Otimix'!O:O)+SUMIF('BD Otimix'!A:A,'BD VOLUME'!AJ31,'BD Otimix'!O:O)+SUMIF('BD Otimix'!A:A,'BD VOLUME'!AF31,'BD Otimix'!O:O),0) -> 0 | AL31: =IFERROR(F31/$E$3/1000/AK31,0) -> 0
A32: 209669 | B32: 209669 | C32: FIGADO FG CG PCT | D32: MIUDOS | E32: FÍGADO PACOTE 1 KG | F32: =SUMIF('COLAR PLANO'!$A:$A,A32,'COLAR PLANO'!$D:$D) -> 42336 | G32: =IFERROR(F32/($E$3*$C$3),0) -> 200.97793 | H32: 0.0175 | I32: =IFERROR(G32/$D$7/H32,0) -> 3828.151 | J32: =IFERROR(I32/$B$7,0) -> 0.81454545 | K32: 1 | L32: 16 | M32: 16 | N32: =IFERROR(G32/K32,"-") -> 200.97793 | P32: =IFERROR(G32/M32,"-") -> 12.56112 | U32: - | V32: FRG | W32: =Preencher!$B$3&U32&V32&A32&$W$6 -> JARINU-FRG209669MQ.TUNEL DE CG (CONTINUO) | X32: =Preencher!$B$3&U32&V32&A32&$X$6 -> JARINU-FRG209669MQ.TUNEL DE CG (CONTINUO) (1) | Y32: =Preencher!$B$3&U32&V32&A32&$Y$6 -> JARINU-FRG209669MQ.TUNEL DE CG (CONTINUO) (2) | Z32: =Preencher!$B$3&U32&V32&A32&$Z$6 -> JARINU-FRG209669MQ.TUNEL DE CG (CONTINUO) (3) | AA32: =Preencher!$B$3&U32&V32&A32&$AA$6 -> JARINU-FRG209669MQ.TUNEL DE CG (ESTATICO) | AB32: =Preencher!$B$3&U32&V32&A32&$AB$6 -> JARINU-FRG209669MQ.TUNEL DE CG (ESTATICO) (1) | AC32: =Preencher!$B$3&U32&V32&A32&$AC$6 -> JARINU-FRG209669MQ.TUNEL DE CG (ESTATICO) (2) | AD32: =IFERROR(SUMIF('BD Otimix'!A:A,'BD VOLUME'!X32,'BD Otimix'!O:O)+SUMIF('BD Otimix'!A:A,'BD VOLUME'!Y32,'BD Otimix'!O:O)+SUMIF('BD Otimix'!A:A,'BD VOLUME'!Z32,'BD Otimix'!O:O)+SUMIF('BD Otimix'!A:A,'BD VOLUME'!AA32,'BD Otimix'!O:O)+SUMIF('BD Otimix'!A:A,'BD VOLUME'!AB32,'BD Otimix'!O:O)+SUMIF('BD Otimix'!A:A,'BD VOLUME'!AC32,'BD Otimix'!O:O)+SUMIF('BD Otimix'!A:A,'BD VOLUME'!W32,'BD Otimix'!O:O),0) -> 0 | AE32: =IFERROR(F32/$E$3/1000/AD32,0) -> 0 | AF32: =Preencher!$B$3&$U$8&$V$8&A32&$AF$6 -> JARINU-FRG209669MQ.GIROFREEZER | AG32: =Preencher!$B$3&$U$8&$V$8&A32&$AG$6 -> JARINU-FRG209669MQ.GIROFREEZER (1) | AH32: =Preencher!$B$3&$U$8&$V$8&A32&$AH$6 -> JARINU-FRG209669MQ.GIROFREEZER (2) | AI32: =Preencher!$B$3&$U$8&$V$8&A32&$AI$6 -> JARINU-FRG209669MQ.GIROFREEZER REV04 | AJ32: =Preencher!$B$3&$U$8&$V$8&A32&$AJ$6 -> JARINU-FRG209669MQ.GIROFREEZER (3) | AK32: =IFERROR(SUMIF('BD Otimix'!A:A,'BD VOLUME'!AG32,'BD Otimix'!O:O)+SUMIF('BD Otimix'!A:A,'BD VOLUME'!AH32,'BD Otimix'!O:O)+SUMIF('BD Otimix'!A:A,'BD VOLUME'!AI32,'BD Otimix'!O:O)+SUMIF('BD Otimix'!A:A,'BD VOLUME'!AJ32,'BD Otimix'!O:O)+SUMIF('BD Otimix'!A:A,'BD VOLUME'!AF32,'BD Otimix'!O:O),0) -> 0 | AL32: =IFERROR(F32/$E$3/1000/AK32,0) -> 0
A33: 124695 | B33: LI-83 | C33: FIGADO FG PB | D33: MIUDOS | E33: Fígado Pacote 0,45 Kg | F33: =SUMIF('COLAR PLANO'!$A:$A,A33,'COLAR PLANO'!$D:$D) -> 0 | G33: =IFERROR(F33/($E$3*$C$3),0) -> 0 | H33: 0.0175 | I33: =IFERROR(G33/$D$7/H33,0) -> 0 | J33: =IFERROR(I33/$B$7,0) -> 0 | K33: 0.5 | L33: 24 | M33: 12 | N33: =IFERROR(G33/K33,"-") -> 0 | P33: =IFERROR(G33/M33,"-") -> 0 | U33: - | V33: FRG | W33: =Preencher!$B$3&U33&V33&A33&$W$6 -> JARINU-FRG124695MQ.TUNEL DE CG (CONTINUO) | X33: =Preencher!$B$3&U33&V33&A33&$X$6 -> JARINU-FRG124695MQ.TUNEL DE CG (CONTINUO) (1) | Y33: =Preencher!$B$3&U33&V33&A33&$Y$6 -> JARINU-FRG124695MQ.TUNEL DE CG (CONTINUO) (2) | Z33: =Preencher!$B$3&U33&V33&A33&$Z$6 -> JARINU-FRG124695MQ.TUNEL DE CG (CONTINUO) (3) | AA33: =Preencher!$B$3&U33&V33&A33&$AA$6 -> JARINU-FRG124695MQ.TUNEL DE CG (ESTATICO) | AB33: =Preencher!$B$3&U33&V33&A33&$AB$6 -> JARINU-FRG124695MQ.TUNEL DE CG (ESTATICO) (1) | AC33: =Preencher!$B$3&U33&V33&A33&$AC$6 -> JARINU-FRG124695MQ.TUNEL DE CG (ESTATICO) (2) | AD33: =IFERROR(SUMIF('BD Otimix'!A:A,'BD VOLUME'!X33,'BD Otimix'!O:O)+SUMIF('BD Otimix'!A:A,'BD VOLUME'!Y33,'BD Otimix'!O:O)+SUMIF('BD Otimix'!A:A,'BD VOLUME'!Z33,'BD Otimix'!O:O)+SUMIF('BD Otimix'!A:A,'BD VOLUME'!AA33,'BD Otimix'!O:O)+SUMIF('BD Otimix'!A:A,'BD VOLUME'!AB33,'BD Otimix'!O:O)+SUMIF('BD Otimix'!A:A,'BD VOLUME'!AC33,'BD Otimix'!O:O)+SUMIF('BD Otimix'!A:A,'BD VOLUME'!W33,'BD Otimix'!O:O),0) -> 0 | AE33: =IFERROR(F33/$E$3/1000/AD33,0) -> 0 | AF33: =Preencher!$B$3&$U$8&$V$8&A33&$AF$6 -> JARINU-FRG124695MQ.GIROFREEZER | AG33: =Preencher!$B$3&$U$8&$V$8&A33&$AG$6 -> JARINU-FRG124695MQ.GIROFREEZER (1) | AH33: =Preencher!$B$3&$U$8&$V$8&A33&$AH$6 -> JARINU-FRG124695MQ.GIROFREEZER (2) | AI33: =Preencher!$B$3&$U$8&$V$8&A33&$AI$6 -> JARINU-FRG124695MQ.GIROFREEZER REV04 | AJ33: =Preencher!$B$3&$U$8&$V$8&A33&$AJ$6 -> JARINU-FRG124695MQ.GIROFREEZER (3) | AK33: =IFERROR(SUMIF('BD Otimix'!A:A,'BD VOLUME'!AG33,'BD Otimix'!O:O)+SUMIF('BD Otimix'!A:A,'BD VOLUME'!AH33,'BD Otimix'!O:O)+SUMIF('BD Otimix'!A:A,'BD VOLUME'!AI33,'BD Otimix'!O:O)+SUMIF('BD Otimix'!A:A,'BD VOLUME'!AJ33,'BD Otimix'!O:O)+SUMIF('BD Otimix'!A:A,'BD VOLUME'!AF33,'BD Otimix'!O:O),0) -> 0 | AL33: =IFERROR(F33/$E$3/1000/AK33,0) -> 0
A34: 236789 | C34: FIGADO FG BDJ GF | D34: MIUDOS | E34: FÍGADO BDJ CG | F34: =SUMIF('COLAR PLANO'!$A:$A,A34,'COLAR PLANO'!$D:$D) -> 0 | G34: =IFERROR(F34/($E$3*$C$3),0) -> 0 | H34: 0.0175 | I34: =IFERROR(G34/$D$7/H34,0) -> 0 | J34: =IFERROR(I34/$B$7,0) -> 0 | K34: 1 | L34: 12 | M34: 12 | N34: =IFERROR(G34/K34,"-") -> 0 | P34: =IFERROR(G34/M34,"-") -> 0 | U34: - | V34: FRG | W34: =Preencher!$B$3&U34&V34&A34&$W$6 -> JARINU-FRG236789MQ.TUNEL DE CG (CONTINUO) | X34: =Preencher!$B$3&U34&V34&A34&$X$6 -> JARINU-FRG236789MQ.TUNEL DE CG (CONTINUO) (1) | Y34: =Preencher!$B$3&U34&V34&A34&$Y$6 -> JARINU-FRG236789MQ.TUNEL DE CG (CONTINUO) (2) | Z34: =Preencher!$B$3&U34&V34&A34&$Z$6 -> JARINU-FRG236789MQ.TUNEL DE CG (CONTINUO) (3) | AA34: =Preencher!$B$3&U34&V34&A34&$AA$6 -> JARINU-FRG236789MQ.TUNEL DE CG (ESTATICO) | AB34: =Preencher!$B$3&U34&V34&A34&$AB$6 -> JARINU-FRG236789MQ.TUNEL DE CG (ESTATICO) (1) | AC34: =Preencher!$B$3&U34&V34&A34&$AC$6 -> JARINU-FRG236789MQ.TUNEL DE CG (ESTATICO) (2) | AD34: =IFERROR(SUMIF('BD Otimix'!A:A,'BD VOLUME'!X34,'BD Otimix'!O:O)+SUMIF('BD Otimix'!A:A,'BD VOLUME'!Y34,'BD Otimix'!O:O)+SUMIF('BD Otimix'!A:A,'BD VOLUME'!Z34,'BD Otimix'!O:O)+SUMIF('BD Otimix'!A:A,'BD VOLUME'!AA34,'BD Otimix'!O:O)+SUMIF('BD Otimix'!A:A,'BD VOLUME'!AB34,'BD Otimix'!O:O)+SUMIF('BD Otimix'!A:A,'BD VOLUME'!AC34,'BD Otimix'!O:O)+SUMIF('BD Otimix'!A:A,'BD VOLUME'!W34,'BD Otimix'!O:O),0) -> 0 | AE34: =IFERROR(F34/$E$3/1000/AD34,0) -> 0 | AF34: =Preencher!$B$3&$U$8&$V$8&A34&$AF$6 -> JARINU-FRG236789MQ.GIROFREEZER | AG34: =Preencher!$B$3&$U$8&$V$8&A34&$AG$6 -> JARINU-FRG236789MQ.GIROFREEZER (1) | AH34: =Preencher!$B$3&$U$8&$V$8&A34&$AH$6 -> JARINU-FRG236789MQ.GIROFREEZER (2) | AI34: =Preencher!$B$3&$U$8&$V$8&A34&$AI$6 -> JARINU-FRG236789MQ.GIROFREEZER REV04 | AJ34: =Preencher!$B$3&$U$8&$V$8&A34&$AJ$6 -> JARINU-FRG236789MQ.GIROFREEZER (3) | AK34: =IFERROR(SUMIF('BD Otimix'!A:A,'BD VOLUME'!AG34,'BD Otimix'!O:O)+SUMIF('BD Otimix'!A:A,'BD VOLUME'!AH34,'BD Otimix'!O:O)+SUMIF('BD Otimix'!A:A,'BD VOLUME'!AI34,'BD Otimix'!O:O)+SUMIF('BD Otimix'!A:A,'BD VOLUME'!AJ34,'BD Otimix'!O:O)+SUMIF('BD Otimix'!A:A,'BD VOLUME'!AF34,'BD Otimix'!O:O),0) -> 0 | AL34: =IFERROR(F34/$E$3/1000/AK34,0) -> 0
A35: 227929 | C35: FIGADO FG BDJ NGF | D35: MIUDOS | E35: FÍGADO BDJ CG | F35: =SUMIF('COLAR PLANO'!$A:$A,A35,'COLAR PLANO'!$D:$D) -> 0 | G35: =IFERROR(F35/($E$3*$C$3),0) -> 0 | H35: 0.0175 | I35: =IFERROR(G35/$D$7/H35,0) -> 0 | J35: =IFERROR(I35/$B$7,0) -> 0 | K35: 1 | L35: 12 | M35: 12 | N35: =IFERROR(G35/K35,"-") -> 0 | P35: =IFERROR(G35/M35,"-") -> 0 | U35: - | V35: FRG | W35: =Preencher!$B$3&U35&V35&A35&$W$6 -> JARINU-FRG227929MQ.TUNEL DE CG (CONTINUO) | X35: =Preencher!$B$3&U35&V35&A35&$X$6 -> JARINU-FRG227929MQ.TUNEL DE CG (CONTINUO) (1) | Y35: =Preencher!$B$3&U35&V35&A35&$Y$6 -> JARINU-FRG227929MQ.TUNEL DE CG (CONTINUO) (2) | Z35: =Preencher!$B$3&U35&V35&A35&$Z$6 -> JARINU-FRG227929MQ.TUNEL DE CG (CONTINUO) (3) | AA35: =Preencher!$B$3&U35&V35&A35&$AA$6 -> JARINU-FRG227929MQ.TUNEL DE CG (ESTATICO) | AB35: =Preencher!$B$3&U35&V35&A35&$AB$6 -> JARINU-FRG227929MQ.TUNEL DE CG (ESTATICO) (1) | AC35: =Preencher!$B$3&U35&V35&A35&$AC$6 -> JARINU-FRG227929MQ.TUNEL DE CG (ESTATICO) (2) | AD35: =IFERROR(SUMIF('BD Otimix'!A:A,'BD VOLUME'!X35,'BD Otimix'!O:O)+SUMIF('BD Otimix'!A:A,'BD VOLUME'!Y35,'BD Otimix'!O:O)+SUMIF('BD Otimix'!A:A,'BD VOLUME'!Z35,'BD Otimix'!O:O)+SUMIF('BD Otimix'!A:A,'BD VOLUME'!AA35,'BD Otimix'!O:O)+SUMIF('BD Otimix'!A:A,'BD VOLUME'!AB35,'BD Otimix'!O:O)+SUMIF('BD Otimix'!A:A,'BD VOLUME'!AC35,'BD Otimix'!O:O)+SUMIF('BD Otimix'!A:A,'BD VOLUME'!W35,'BD Otimix'!O:O),0) -> 0 | AE35: =IFERROR(F35/$E$3/1000/AD35,0) -> 0 | AF35: =Preencher!$B$3&$U$8&$V$8&A35&$AF$6 -> JARINU-FRG227929MQ.GIROFREEZER | AG35: =Preencher!$B$3&$U$8&$V$8&A35&$AG$6 -> JARINU-FRG227929MQ.GIROFREEZER (1) | AH35: =Preencher!$B$3&$U$8&$V$8&A35&$AH$6 -> JARINU-FRG227929MQ.GIROFREEZER (2) | AI35: =Preencher!$B$3&$U$8&$V$8&A35&$AI$6 -> JARINU-FRG227929MQ.GIROFREEZER REV04 | AJ35: =Preencher!$B$3&$U$8&$V$8&A35&$AJ$6 -> JARINU-FRG227929MQ.GIROFREEZER (3) | AK35: =IFERROR(SUMIF('BD Otimix'!A:A,'BD VOLUME'!AG35,'BD Otimix'!O:O)+SUMIF('BD Otimix'!A:A,'BD VOLUME'!AH35,'BD Otimix'!O:O)+SUMIF('BD Otimix'!A:A,'BD VOLUME'!AI35,'BD Otimix'!O:O)+SUMIF('BD Otimix'!A:A,'BD VOLUME'!AJ35,'BD Otimix'!O:O)+SUMIF('BD Otimix'!A:A,'BD VOLUME'!AF35,'BD Otimix'!O:O),0) -> 0 | AL35: =IFERROR(F35/$E$3/1000/AK35,0) -> 0
